Workbook

Sheet Instructions
A1: Data Entry Accuracy & Speed Tracker
A2: Bulk Customer Record Entry | Validation Rules | Speed & Accuracy Measurement
A4: PROJECT OVERVIEW
A5: This tool simulates a real MIS / Data Entry workflow: raw customer records are entered into a
A6: structured Excel sheet, checked automatically against data validation rules, and each entry batch
A7: is timed to measure typing speed (WPM) and accuracy.
A9: SHEETS IN THIS WORKBOOK
A10: 1. Instructions - this page
A11: 2. Data_Entry - structured entry grid with dropdowns, validation formulas and error flags
A12: 3. Speed_Accuracy_Tracker - batch-wise typing speed (WPM) and accuracy % dashboard
A13: 4. Lists - lookup lists used for dropdown validation (State, Payment Mode, Product) - reference only
A15: COLOR LEGEND (Data_Entry sheet)
... A43: extended down to row 701 - they will calculate automatically as you type.

Sheet Lists
A1: Valid_States | B1: Valid_Payment_Modes | C1: Valid_Products
A2: Odisha | B2: Cash | C2: Wireless Mouse
A3: West Bengal | B3: UPI | C3: Office Chair
A4: Bihar | B4: Credit Card | C4: LED Desk Lamp
A5: Jharkhand | B5: Debit Card | C5: Laptop Stand
A6: Chhattisgarh | B6: Net Banking | C6: Bluetooth Speaker
A7: Maharashtra | B7: Cheque | C7: Printer Cartridge
A8: Delhi | C8: A4 Paper Ream
A9: Uttar Pradesh | C9: USB Hard Drive
A10: Madhya Pradesh | C10: Keyboard
A11: Karnataka | C11: Webcam
A12: Tamil Nadu | C12: Whiteboard Marker Set
A13: Telangana | C13: File Organizer
A14: Andhra Pradesh | C14: Power Bank
A15: Gujarat | C15: Wall Clock
A16: Rajasthan | C16: Table Fan
A17: Punjab
A18: Kerala
A19: Assam
A20: Haryana

Sheet Data_Entry
A1: S.No | B1: Batch_No | C1: Customer_ID | D1: Full_Name | E1: Phone_Number | F1: Email | G1: Address | H1: City | I1: State | J1: Pincode | K1: Date_of_Registration | L1: Product_Purchased | M1: Amount_Paid | N1: Payment_Mode | O1: Word_Count | P1: Validation_Status | Q1: Error_Details | R1: Duplicate_Flag
A2: 1 | B2: 1 | C2: CUST00001 | D2: Aryan Maharaj | E2: 9332181960 | F2: aryan.maharaj31@gmail.com | G2: 218, Sami Zila | H2: Ranchi | I2: Jharkhand | J2: 338908 | K2: 12/02/2024 | L2: File Organizer | M2: 10467.17 | N2: Net Banking | O2: =IFERROR(LEN(C2&D2&E2&F2&G2&H2&I2&J2&K2&L2&M2&N2)/5,0) -> 27 | P2: =IF(OR(D2="",C2=""),"",IF((IFERROR(IF(AND(TRIM(D2)=D2,LEN(D2)>0),0,1),1)+IFERROR(IF(AND(LEN(E2)=10,ISNUMBER(VALUE(E2))),0,1),1)+IFERROR(IF(AND(ISNUMBER(SEARCH("@",F2)),ISNUMBER(SEARCH(".",F2))),0,1),1)+IFERROR(IF(AND(LEN(J2)=6,ISNUMBER(VALUE(J2))),0,1),1)+IFERROR(IF(ISNUMBER(MATCH(TRIM(I2),Lists!$A$2:$A$20,0)),0,1),1)+IFERROR(IF(AND(LEN(K2)=10,VALUE(LEFT(K2,FIND("/",K2)-1))>=1,VALUE(LEFT(K2,FIND("/",K2)-1))<=31,VALUE(LEFT(MID(K2,FIND("/",K2)+1,10),FIND("/",MID(K2,FIND("/",K2)+1,10))-1))>=1,VALUE(LEFT(MID(K2,FIND("/",K2)+1,10),FIND("/",MID(K2,FIND("/",K2)+1,10))-1))<=12,VALUE(LEFT(K2,FIND("/",K2)-1))<=DAY(EOMONTH(DATE(VALUE(MID(MID(K2,FIND("/",K2)+1,10),FIND("/",MID(K2,FIND("/",K2)+1,10))+1,4)),VALUE(LEFT(MID(K2,FIND("/",K2)+1,10),FIND("/",MID(K2,FIND("/",K2)+1,10))-1)),1),0))),0,1),1)+IFERROR(IF(M2>=0,0,1),1)+IFERROR(IF(ISNUMBER(MATCH(N2,Lists!$B$2:$B$7,0)),0,1),1))=0,"OK","ERROR")) -> OK | Q2: =IF(D2="","",TRIM(IF(IFERROR(IF(AND(TRIM(D2)=D2,LEN(D2)>0),0,1),1)=1,"Name; ","")&IF(IFERROR(IF(AND(LEN(E2)=10,ISNUMBER(VALUE(E2))),0,1),1)=1,"Phone; ","")&IF(IFERROR(IF(AND(ISNUMBER(SEARCH("@",F2)),ISNUMBER(SEARCH(".",F2))),0,1),1)=1,"Email; ","")&IF(IFERROR(IF(AND(LEN(J2)=6,ISNUMBER(VALUE(J2))),0,1),1)=1,"Pincode; ","")&IF(IFERROR(IF(ISNUMBER(MATCH(TRIM(I2),Lists!$A$2:$A$20,0)),0,1),1)=1,"State; ","")&IF(IFERROR(IF(AND(LEN(K2)=10,VALUE(LEFT(K2,FIND("/",K2)-1))>=1,VALUE(LEFT(K2,FIND("/",K2)-1))<=31,VALUE(LEFT(MID(K2,FIND("/",K2)+1,10),FIND("/",MID(K2,FIND("/",K2)+1,10))-1))>=1,VALUE(LEFT(MID(K2,FIND("/",K2)+1,10),FIND("/",MID(K2,FIND("/",K2)+1,10))-1))<=12,VALUE(LEFT(K2,FIND("/",K2)-1))<=DAY(EOMONTH(DATE(VALUE(MID(MID(K2,FIND("/",K2)+1,10),FIND("/",MID(K2,FIND("/",K2)+1,10))+1,4)),VALUE(LEFT(MID(K2,FIND("/",K2)+1,10),FIND("/",MID(K2,FIND("/",K2)+1,10))-1)),1),0))),0,1),1)=1,"Date; ","")&IF(IFERROR(IF(M2>=0,0,1),1)=1,"Amount; ","")&IF(IFERROR(IF(ISNUMBER(MATCH(N2,Lists!$B$2:$B$7,0)),0,1),1)=1,"Payment; ",""))) | R2: =IF(D2="","",IF(COUNTIFS($D$2:$D$701,D2,$E$2:$E$701,E2)>1,"DUPLICATE","Unique")) -> Unique
A3: 2 | B3: 1 | C3: CUST00002 | D3: Ayushman Chander | E3: 9402654235 | F3: ayushman.chander105@gmail.com | G3: 890, Issac Circle | H3: Ahmedabad | I3: Gujarat | J3: 615594 | K3: 30/03/2023 | L3: File Organizer | M3: 7457.91 | N3: Cash | O3: =IFERROR(LEN(C3&D3&E3&F3&G3&H3&I3&J3&K3&L3&M3&N3)/5,0) -> 27.6 | P3: =IF(OR(D3="",C3=""),"",IF((IFERROR(IF(AND(TRIM(D3)=D3,LEN(D3)>0),0,1),1)+IFERROR(IF(AND(LEN(E3)=10,ISNUMBER(VALUE(E3))),0,1),1)+IFERROR(IF(AND(ISNUMBER(SEARCH("@",F3)),ISNUMBER(SEARCH(".",F3))),0,1),1)+IFERROR(IF(AND(LEN(J3)=6,ISNUMBER(VALUE(J3))),0,1),1)+IFERROR(IF(ISNUMBER(MATCH(TRIM(I3),Lists!$A$2:$A$20,0)),0,1),1)+IFERROR(IF(AND(LEN(K3)=10,VALUE(LEFT(K3,FIND("/",K3)-1))>=1,VALUE(LEFT(K3,FIND("/",K3)-1))<=31,VALUE(LEFT(MID(K3,FIND("/",K3)+1,10),FIND("/",MID(K3,FIND("/",K3)+1,10))-1))>=1,VALUE(LEFT(MID(K3,FIND("/",K3)+1,10),FIND("/",MID(K3,FIND("/",K3)+1,10))-1))<=12,VALUE(LEFT(K3,FIND("/",K3)-1))<=DAY(EOMONTH(DATE(VALUE(MID(MID(K3,FIND("/",K3)+1,10),FIND("/",MID(K3,FIND("/",K3)+1,10))+1,4)),VALUE(LEFT(MID(K3,FIND("/",K3)+1,10),FIND("/",MID(K3,FIND("/",K3)+1,10))-1)),1),0))),0,1),1)+IFERROR(IF(M3>=0,0,1),1)+IFERROR(IF(ISNUMBER(MATCH(N3,Lists!$B$2:$B$7,0)),0,1),1))=0,"OK","ERROR")) -> OK | Q3: =IF(D3="","",TRIM(IF(IFERROR(IF(AND(TRIM(D3)=D3,LEN(D3)>0),0,1),1)=1,"Name; ","")&IF(IFERROR(IF(AND(LEN(E3)=10,ISNUMBER(VALUE(E3))),0,1),1)=1,"Phone; ","")&IF(IFERROR(IF(AND(ISNUMBER(SEARCH("@",F3)),ISNUMBER(SEARCH(".",F3))),0,1),1)=1,"Email; ","")&IF(IFERROR(IF(AND(LEN(J3)=6,ISNUMBER(VALUE(J3))),0,1),1)=1,"Pincode; ","")&IF(IFERROR(IF(ISNUMBER(MATCH(TRIM(I3),Lists!$A$2:$A$20,0)),0,1),1)=1,"State; ","")&IF(IFERROR(IF(AND(LEN(K3)=10,VALUE(LEFT(K3,FIND("/",K3)-1))>=1,VALUE(LEFT(K3,FIND("/",K3)-1))<=31,VALUE(LEFT(MID(K3,FIND("/",K3)+1,10),FIND("/",MID(K3,FIND("/",K3)+1,10))-1))>=1,VALUE(LEFT(MID(K3,FIND("/",K3)+1,10),FIND("/",MID(K3,FIND("/",K3)+1,10))-1))<=12,VALUE(LEFT(K3,FIND("/",K3)-1))<=DAY(EOMONTH(DATE(VALUE(MID(MID(K3,FIND("/",K3)+1,10),FIND("/",MID(K3,FIND("/",K3)+1,10))+1,4)),VALUE(LEFT(MID(K3,FIND("/",K3)+1,10),FIND("/",MID(K3,FIND("/",K3)+1,10))-1)),1),0))),0,1),1)=1,"Date; ","")&IF(IFERROR(IF(M3>=0,0,1),1)=1,"Amount; ","")&IF(IFERROR(IF(ISNUMBER(MATCH(N3,Lists!$B$2:$B$7,0)),0,1),1)=1,"Payment; ",""))) | R3: =IF(D3="","",IF(COUNTIFS($D$2:$D$701,D3,$E$2:$E$701,E3)>1,"DUPLICATE","Unique")) -> Unique
A4: 3 | B4: 1 | C4: CUST00003 | D4: Thomas Sen | E4: 9959310341 | F4: thomas.sen876@gmail.com | G4: H.No. 265, Dugal Road | H4: Vijayawada | I4: Andhra Pradesh | J4: 164752 | K4: 28/01/2025 | L4: Printer Cartridge | M4: 3509.21 | N4: Credit Card | O4: =IFERROR(LEN(C4&D4&E4&F4&G4&H4&I4&J4&K4&L4&M4&N4)/5,0) -> 29.6 | P4: =IF(OR(D4="",C4=""),"",IF((IFERROR(IF(AND(TRIM(D4)=D4,LEN(D4)>0),0,1),1)+IFERROR(IF(AND(LEN(E4)=10,ISNUMBER(VALUE(E4))),0,1),1)+IFERROR(IF(AND(ISNUMBER(SEARCH("@",F4)),ISNUMBER(SEARCH(".",F4))),0,1),1)+IFERROR(IF(AND(LEN(J4)=6,ISNUMBER(VALUE(J4))),0,1),1)+IFERROR(IF(ISNUMBER(MATCH(TRIM(I4),Lists!$A$2:$A$20,0)),0,1),1)+IFERROR(IF(AND(LEN(K4)=10,VALUE(LEFT(K4,FIND("/",K4)-1))>=1,VALUE(LEFT(K4,FIND("/",K4)-1))<=31,VALUE(LEFT(MID(K4,FIND("/",K4)+1,10),FIND("/",MID(K4,FIND("/",K4)+1,10))-1))>=1,VALUE(LEFT(MID(K4,FIND("/",K4)+1,10),FIND("/",MID(K4,FIND("/",K4)+1,10))-1))<=12,VALUE(LEFT(K4,FIND("/",K4)-1))<=DAY(EOMONTH(DATE(VALUE(MID(MID(K4,FIND("/",K4)+1,10),FIND("/",MID(K4,FIND("/",K4)+1,10))+1,4)),VALUE(LEFT(MID(K4,FIND("/",K4)+1,10),FIND("/",MID(K4,FIND("/",K4)+1,10))-1)),1),0))),0,1),1)+IFERROR(IF(M4>=0,0,1),1)+IFERROR(IF(ISNUMBER(MATCH(N4,Lists!$B$2:$B$7,0)),0,1),1))=0,"OK","ERROR")) -> OK | Q4: =IF(D4="","",TRIM(IF(IFERROR(IF(AND(TRIM(D4)=D4,LEN(D4)>0),0,1),1)=1,"Name; ","")&IF(IFERROR(IF(AND(LEN(E4)=10,ISNUMBER(VALUE(E4))),0,1),1)=1,"Phone; ","")&IF(IFERROR(IF(AND(ISNUMBER(SEARCH("@",F4)),ISNUMBER(SEARCH(".",F4))),0,1),1)=1,"Email; ","")&IF(IFERROR(IF(AND(LEN(J4)=6,ISNUMBER(VALUE(J4))),0,1),1)=1,"Pincode; ","")&IF(IFERROR(IF(ISNUMBER(MATCH(TRIM(I4),Lists!$A$2:$A$20,0)),0,1),1)=1,"State; ","")&IF(IFERROR(IF(AND(LEN(K4)=10,VALUE(LEFT(K4,FIND("/",K4)-1))>=1,VALUE(LEFT(K4,FIND("/",K4)-1))<=31,VALUE(LEFT(MID(K4,FIND("/",K4)+1,10),FIND("/",MID(K4,FIND("/",K4)+1,10))-1))>=1,VALUE(LEFT(MID(K4,FIND("/",K4)+1,10),FIND("/",MID(K4,FIND("/",K4)+1,10))-1))<=12,VALUE(LEFT(K4,FIND("/",K4)-1))<=DAY(EOMONTH(DATE(VALUE(MID(MID(K4,FIND("/",K4)+1,10),FIND("/",MID(K4,FIND("/",K4)+1,10))+1,4)),VALUE(LEFT(MID(K4,FIND("/",K4)+1,10),FIND("/",MID(K4,FIND("/",K4)+1,10))-1)),1),0))),0,1),1)=1,"Date; ","")&IF(IFERROR(IF(M4>=0,0,1),1)=1,"Amount; ","")&IF(IFERROR(IF(ISNUMBER(MATCH(N4,Lists!$B$2:$B$7,0)),0,1),1)=1,"Payment; ",""))) | R4: =IF(D4="","",IF(COUNTIFS($D$2:$D$701,D4,$E$2:$E$701,E4)>1,"DUPLICATE","Unique")) -> Unique
A5: 4 | B5: 1 | C5: CUST00004 | D5: Gayathri Chaudry | E5: 9832764835 | F5: gayathri.chaudry864@gmail.com | G5: 15, Lalla Path | H5: Bhagalpur | I5: Bihar | J5: 305641 | K5: 08/03/2024 | L5: Table Fan | M5: 15096.97 | N5: Cheque | O5: =IFERROR(LEN(C5&D5&E5&F5&G5&H5&I5&J5&K5&L5&M5&N5)/5,0) -> 26.2 | P5: =IF(OR(D5="",C5=""),"",IF((IFERROR(IF(AND(TRIM(D5)=D5,LEN(D5)>0),0,1),1)+IFERROR(IF(AND(LEN(E5)=10,ISNUMBER(VALUE(E5))),0,1),1)+IFERROR(IF(AND(ISNUMBER(SEARCH("@",F5)),ISNUMBER(SEARCH(".",F5))),0,1),1)+IFERROR(IF(AND(LEN(J5)=6,ISNUMBER(VALUE(J5))),0,1),1)+IFERROR(IF(ISNUMBER(MATCH(TRIM(I5),Lists!$A$2:$A$20,0)),0,1),1)+IFERROR(IF(AND(LEN(K5)=10,VALUE(LEFT(K5,FIND("/",K5)-1))>=1,VALUE(LEFT(K5,FIND("/",K5)-1))<=31,VALUE(LEFT(MID(K5,FIND("/",K5)+1,10),FIND("/",MID(K5,FIND("/",K5)+1,10))-1))>=1,VALUE(LEFT(MID(K5,FIND("/",K5)+1,10),FIND("/",MID(K5,FIND("/",K5)+1,10))-1))<=12,VALUE(LEFT(K5,FIND("/",K5)-1))<=DAY(EOMONTH(DATE(VALUE(MID(MID(K5,FIND("/",K5)+1,10),FIND("/",MID(K5,FIND("/",K5)+1,10))+1,4)),VALUE(LEFT(MID(K5,FIND("/",K5)+1,10),FIND("/",MID(K5,FIND("/",K5)+1,10))-1)),1),0))),0,1),1)+IFERROR(IF(M5>=0,0,1),1)+IFERROR(IF(ISNUMBER(MATCH(N5,Lists!$B$2:$B$7,0)),0,1),1))=0,"OK","ERROR")) -> OK | Q5: =IF(D5="","",TRIM(IF(IFERROR(IF(AND(TRIM(D5)=D5,LEN(D5)>0),0,1),1)=1,"Name; ","")&IF(IFERROR(IF(AND(LEN(E5)=10,ISNUMBER(VALUE(E5))),0,1),1)=1,"Phone; ","")&IF(IFERROR(IF(AND(ISNUMBER(SEARCH("@",F5)),ISNUMBER(SEARCH(".",F5))),0,1),1)=1,"Email; ","")&IF(IFERROR(IF(AND(LEN(J5)=6,ISNUMBER(VALUE(J5))),0,1),1)=1,"Pincode; ","")&IF(IFERROR(IF(ISNUMBER(MATCH(TRIM(I5),Lists!$A$2:$A$20,0)),0,1),1)=1,"State; ","")&IF(IFERROR(IF(AND(LEN(K5)=10,VALUE(LEFT(K5,FIND("/",K5)-1))>=1,VALUE(LEFT(K5,FIND("/",K5)-1))<=31,VALUE(LEFT(MID(K5,FIND("/",K5)+1,10),FIND("/",MID(K5,FIND("/",K5)+1,10))-1))>=1,VALUE(LEFT(MID(K5,FIND("/",K5)+1,10),FIND("/",MID(K5,FIND("/",K5)+1,10))-1))<=12,VALUE(LEFT(K5,FIND("/",K5)-1))<=DAY(EOMONTH(DATE(VALUE(MID(MID(K5,FIND("/",K5)+1,10),FIND("/",MID(K5,FIND("/",K5)+1,10))+1,4)),VALUE(LEFT(MID(K5,FIND("/",K5)+1,10),FIND("/",MID(K5,FIND("/",K5)+1,10))-1)),1),0))),0,1),1)=1,"Date; ","")&IF(IFERROR(IF(M5>=0,0,1),1)=1,"Amount; ","")&IF(IFERROR(IF(ISNUMBER(MATCH(N5,Lists!$B$2:$B$7,0)),0,1),1)=1,"Payment; ",""))) | R5: =IF(D5="","",IF(COUNTIFS($D$2:$D$701,D5,$E$2:$E$701,E5)>1,"DUPLICATE","Unique")) -> Unique
A6: 5 | B6: 1 | C6: CUST00005 | D6: Tripti Yadav | E6: 9672423884 | F6: tripti.yadav765@outlook.com | G6: 18, Pathak Road | H6: Chennai | I6: Tamil Nadu | J6: 696532 | K6: 09/11/2025 | L6: USB Hard Drive | M6: 1635.37 | N6: Cash | O6: =IFERROR(LEN(C6&D6&E6&F6&G6&H6&I6&J6&K6&L6&M6&N6)/5,0) -> 26.2 | P6: =IF(OR(D6="",C6=""),"",IF((IFERROR(IF(AND(TRIM(D6)=D6,LEN(D6)>0),0,1),1)+IFERROR(IF(AND(LEN(E6)=10,ISNUMBER(VALUE(E6))),0,1),1)+IFERROR(IF(AND(ISNUMBER(SEARCH("@",F6)),ISNUMBER(SEARCH(".",F6))),0,1),1)+IFERROR(IF(AND(LEN(J6)=6,ISNUMBER(VALUE(J6))),0,1),1)+IFERROR(IF(ISNUMBER(MATCH(TRIM(I6),Lists!$A$2:$A$20,0)),0,1),1)+IFERROR(IF(AND(LEN(K6)=10,VALUE(LEFT(K6,FIND("/",K6)-1))>=1,VALUE(LEFT(K6,FIND("/",K6)-1))<=31,VALUE(LEFT(MID(K6,FIND("/",K6)+1,10),FIND("/",MID(K6,FIND("/",K6)+1,10))-1))>=1,VALUE(LEFT(MID(K6,FIND("/",K6)+1,10),FIND("/",MID(K6,FIND("/",K6)+1,10))-1))<=12,VALUE(LEFT(K6,FIND("/",K6)-1))<=DAY(EOMONTH(DATE(VALUE(MID(MID(K6,FIND("/",K6)+1,10),FIND("/",MID(K6,FIND("/",K6)+1,10))+1,4)),VALUE(LEFT(MID(K6,FIND("/",K6)+1,10),FIND("/",MID(K6,FIND("/",K6)+1,10))-1)),1),0))),0,1),1)+IFERROR(IF(M6>=0,0,1),1)+IFERROR(IF(ISNUMBER(MATCH(N6,Lists!$B$2:$B$7,0)),0,1),1))=0,"OK","ERROR")) -> OK | Q6: =IF(D6="","",TRIM(IF(IFERROR(IF(AND(TRIM(D6)=D6,LEN(D6)>0),0,1),1)=1,"Name; ","")&IF(IFERROR(IF(AND(LEN(E6)=10,ISNUMBER(VALUE(E6))),0,1),1)=1,"Phone; ","")&IF(IFERROR(IF(AND(ISNUMBER(SEARCH("@",F6)),ISNUMBER(SEARCH(".",F6))),0,1),1)=1,"Email; ","")&IF(IFERROR(IF(AND(LEN(J6)=6,ISNUMBER(VALUE(J6))),0,1),1)=1,"Pincode; ","")&IF(IFERROR(IF(ISNUMBER(MATCH(TRIM(I6),Lists!$A$2:$A$20,0)),0,1),1)=1,"State; ","")&IF(IFERROR(IF(AND(LEN(K6)=10,VALUE(LEFT(K6,FIND("/",K6)-1))>=1,VALUE(LEFT(K6,FIND("/",K6)-1))<=31,VALUE(LEFT(MID(K6,FIND("/",K6)+1,10),FIND("/",MID(K6,FIND("/",K6)+1,10))-1))>=1,VALUE(LEFT(MID(K6,FIND("/",K6)+1,10),FIND("/",MID(K6,FIND("/",K6)+1,10))-1))<=12,VALUE(LEFT(K6,FIND("/",K6)-1))<=DAY(EOMONTH(DATE(VALUE(MID(MID(K6,FIND("/",K6)+1,10),FIND("/",MID(K6,FIND("/",K6)+1,10))+1,4)),VALUE(LEFT(MID(K6,FIND("/",K6)+1,10),FIND("/",MID(K6,FIND("/",K6)+1,10))-1)),1),0))),0,1),1)=1,"Date; ","")&IF(IFERROR(IF(M6>=0,0,1),1)=1,"Amount; ","")&IF(IFERROR(IF(ISNUMBER(MATCH(N6,Lists!$B$2:$B$7,0)),0,1),1)=1,"Payment; ",""))) | R6: =IF(D6="","",IF(COUNTIFS($D$2:$D$701,D6,$E$2:$E$701,E6)>1,"DUPLICATE","Unique")) -> Unique
A7: 6 | B7: 1 | C7: CUST00006 | D7: Ekaraj Bath | E7: 9691669784 | F7: ekaraj.bath995@outlook.com | G7: H.No. 13, Rai Zila | H7: Ranchi | I7: Jharkhand | J7: 018451 | K7: 24/08/2024 | L7: A4 Paper Ream | M7: 2697.89 | N7: Cash | O7: =IFERROR(LEN(C7&D7&E7&F7&G7&H7&I7&J7&K7&L7&M7&N7)/5,0) -> 25.8 | P7: =IF(OR(D7="",C7=""),"",IF((IFERROR(IF(AND(TRIM(D7)=D7,LEN(D7)>0),0,1),1)+IFERROR(IF(AND(LEN(E7)=10,ISNUMBER(VALUE(E7))),0,1),1)+IFERROR(IF(AND(ISNUMBER(SEARCH("@",F7)),ISNUMBER(SEARCH(".",F7))),0,1),1)+IFERROR(IF(AND(LEN(J7)=6,ISNUMBER(VALUE(J7))),0,1),1)+IFERROR(IF(ISNUMBER(MATCH(TRIM(I7),Lists!$A$2:$A$20,0)),0,1),1)+IFERROR(IF(AND(LEN(K7)=10,VALUE(LEFT(K7,FIND("/",K7)-1))>=1,VALUE(LEFT(K7,FIND("/",K7)-1))<=31,VALUE(LEFT(MID(K7,FIND("/",K7)+1,10),FIND("/",MID(K7,FIND("/",K7)+1,10))-1))>=1,VALUE(LEFT(MID(K7,FIND("/",K7)+1,10),FIND("/",MID(K7,FIND("/",K7)+1,10))-1))<=12,VALUE(LEFT(K7,FIND("/",K7)-1))<=DAY(EOMONTH(DATE(VALUE(MID(MID(K7,FIND("/",K7)+1,10),FIND("/",MID(K7,FIND("/",K7)+1,10))+1,4)),VALUE(LEFT(MID(K7,FIND("/",K7)+1,10),FIND("/",MID(K7,FIND("/",K7)+1,10))-1)),1),0))),0,1),1)+IFERROR(IF(M7>=0,0,1),1)+IFERROR(IF(ISNUMBER(MATCH(N7,Lists!$B$2:$B$7,0)),0,1),1))=0,"OK","ERROR")) -> OK | Q7: =IF(D7="","",TRIM(IF(IFERROR(IF(AND(TRIM(D7)=D7,LEN(D7)>0),0,1),1)=1,"Name; ","")&IF(IFERROR(IF(AND(LEN(E7)=10,ISNUMBER(VALUE(E7))),0,1),1)=1,"Phone; ","")&IF(IFERROR(IF(AND(ISNUMBER(SEARCH("@",F7)),ISNUMBER(SEARCH(".",F7))),0,1),1)=1,"Email; ","")&IF(IFERROR(IF(AND(LEN(J7)=6,ISNUMBER(VALUE(J7))),0,1),1)=1,"Pincode; ","")&IF(IFERROR(IF(ISNUMBER(MATCH(TRIM(I7),Lists!$A$2:$A$20,0)),0,1),1)=1,"State; ","")&IF(IFERROR(IF(AND(LEN(K7)=10,VALUE(LEFT(K7,FIND("/",K7)-1))>=1,VALUE(LEFT(K7,FIND("/",K7)-1))<=31,VALUE(LEFT(MID(K7,FIND("/",K7)+1,10),FIND("/",MID(K7,FIND("/",K7)+1,10))-1))>=1,VALUE(LEFT(MID(K7,FIND("/",K7)+1,10),FIND("/",MID(K7,FIND("/",K7)+1,10))-1))<=12,VALUE(LEFT(K7,FIND("/",K7)-1))<=DAY(EOMONTH(DATE(VALUE(MID(MID(K7,FIND("/",K7)+1,10),FIND("/",MID(K7,FIND("/",K7)+1,10))+1,4)),VALUE(LEFT(MID(K7,FIND("/",K7)+1,10),FIND("/",MID(K7,FIND("/",K7)+1,10))-1)),1),0))),0,1),1)=1,"Date; ","")&IF(IFERROR(IF(M7>=0,0,1),1)=1,"Amount; ","")&IF(IFERROR(IF(ISNUMBER(MATCH(N7,Lists!$B$2:$B$7,0)),0,1),1)=1,"Payment; ",""))) | R7: =IF(D7="","",IF(COUNTIFS($D$2:$D$701,D7,$E$2:$E$701,E7)>1,"DUPLICATE","Unique")) -> Unique
A8: 7 | B8: 1 | C8: CUST00007 | D8: Sudiksha Patla | E8: 9814893252 | F8: sudiksha.patla553@outlook.com | G8: H.No. 53, Bora Road | H8: Jabalpur | I8: Madhya Pradesh | J8: 095701 | K8: 13/01/2025 | L8: Table Fan | M8: 15767.08 | N8: Credit Card | O8: =IFERROR(LEN(C8&D8&E8&F8&G8&H8&I8&J8&K8&L8&M8&N8)/5,0) -> 29.4 | P8: =IF(OR(D8="",C8=""),"",IF((IFERROR(IF(AND(TRIM(D8)=D8,LEN(D8)>0),0,1),1)+IFERROR(IF(AND(LEN(E8)=10,ISNUMBER(VALUE(E8))),0,1),1)+IFERROR(IF(AND(ISNUMBER(SEARCH("@",F8)),ISNUMBER(SEARCH(".",F8))),0,1),1)+IFERROR(IF(AND(LEN(J8)=6,ISNUMBER(VALUE(J8))),0,1),1)+IFERROR(IF(ISNUMBER(MATCH(TRIM(I8),Lists!$A$2:$A$20,0)),0,1),1)+IFERROR(IF(AND(LEN(K8)=10,VALUE(LEFT(K8,FIND("/",K8)-1))>=1,VALUE(LEFT(K8,FIND("/",K8)-1))<=31,VALUE(LEFT(MID(K8,FIND("/",K8)+1,10),FIND("/",MID(K8,FIND("/",K8)+1,10))-1))>=1,VALUE(LEFT(MID(K8,FIND("/",K8)+1,10),FIND("/",MID(K8,FIND("/",K8)+1,10))-1))<=12,VALUE(LEFT(K8,FIND("/",K8)-1))<=DAY(EOMONTH(DATE(VALUE(MID(MID(K8,FIND("/",K8)+1,10),FIND("/",MID(K8,FIND("/",K8)+1,10))+1,4)),VALUE(LEFT(MID(K8,FIND("/",K8)+1,10),FIND("/",MID(K8,FIND("/",K8)+1,10))-1)),1),0))),0,1),1)+IFERROR(IF(M8>=0,0,1),1)+IFERROR(IF(ISNUMBER(MATCH(N8,Lists!$B$2:$B$7,0)),0,1),1))=0,"OK","ERROR")) -> OK | Q8: =IF(D8="","",TRIM(IF(IFERROR(IF(AND(TRIM(D8)=D8,LEN(D8)>0),0,1),1)=1,"Name; ","")&IF(IFERROR(IF(AND(LEN(E8)=10,ISNUMBER(VALUE(E8))),0,1),1)=1,"Phone; ","")&IF(IFERROR(IF(AND(ISNUMBER(SEARCH("@",F8)),ISNUMBER(SEARCH(".",F8))),0,1),1)=1,"Email; ","")&IF(IFERROR(IF(AND(LEN(J8)=6,ISNUMBER(VALUE(J8))),0,1),1)=1,"Pincode; ","")&IF(IFERROR(IF(ISNUMBER(MATCH(TRIM(I8),Lists!$A$2:$A$20,0)),0,1),1)=1,"State; ","")&IF(IFERROR(IF(AND(LEN(K8)=10,VALUE(LEFT(K8,FIND("/",K8)-1))>=1,VALUE(LEFT(K8,FIND("/",K8)-1))<=31,VALUE(LEFT(MID(K8,FIND("/",K8)+1,10),FIND("/",MID(K8,FIND("/",K8)+1,10))-1))>=1,VALUE(LEFT(MID(K8,FIND("/",K8)+1,10),FIND("/",MID(K8,FIND("/",K8)+1,10))-1))<=12,VALUE(LEFT(K8,FIND("/",K8)-1))<=DAY(EOMONTH(DATE(VALUE(MID(MID(K8,FIND("/",K8)+1,10),FIND("/",MID(K8,FIND("/",K8)+1,10))+1,4)),VALUE(LEFT(MID(K8,FIND("/",K8)+1,10),FIND("/",MID(K8,FIND("/",K8)+1,10))-1)),1),0))),0,1),1)=1,"Date; ","")&IF(IFERROR(IF(M8>=0,0,1),1)=1,"Amount; ","")&IF(IFERROR(IF(ISNUMBER(MATCH(N8,Lists!$B$2:$B$7,0)),0,1),1)=1,"Payment; ",""))) | R8: =IF(D8="","",IF(COUNTIFS($D$2:$D$701,D8,$E$2:$E$701,E8)>1,"DUPLICATE","Unique")) -> Unique
A9: 8 | B9: 1 | C9: CUST00008 | D9: Yash Gade | E9: 9911718227 | F9: yash.gade970@outlook.com | G9: 48, Nair Ganj | H9: Lucknow | I9: Uttar Pradesh | J9: 248963 | K9: 09/01/2026 | L9: Power Bank | M9: 11731.91 | N9: UPI | O9: =IFERROR(LEN(C9&D9&E9&F9&G9&H9&I9&J9&K9&L9&M9&N9)/5,0) -> 24.4 | P9: =IF(OR(D9="",C9=""),"",IF((IFERROR(IF(AND(TRIM(D9)=D9,LEN(D9)>0),0,1),1)+IFERROR(IF(AND(LEN(E9)=10,ISNUMBER(VALUE(E9))),0,1),1)+IFERROR(IF(AND(ISNUMBER(SEARCH("@",F9)),ISNUMBER(SEARCH(".",F9))),0,1),1)+IFERROR(IF(AND(LEN(J9)=6,ISNUMBER(VALUE(J9))),0,1),1)+IFERROR(IF(ISNUMBER(MATCH(TRIM(I9),Lists!$A$2:$A$20,0)),0,1),1)+IFERROR(IF(AND(LEN(K9)=10,VALUE(LEFT(K9,FIND("/",K9)-1))>=1,VALUE(LEFT(K9,FIND("/",K9)-1))<=31,VALUE(LEFT(MID(K9,FIND("/",K9)+1,10),FIND("/",MID(K9,FIND("/",K9)+1,10))-1))>=1,VALUE(LEFT(MID(K9,FIND("/",K9)+1,10),FIND("/",MID(K9,FIND("/",K9)+1,10))-1))<=12,VALUE(LEFT(K9,FIND("/",K9)-1))<=DAY(EOMONTH(DATE(VALUE(MID(MID(K9,FIND("/",K9)+1,10),FIND("/",MID(K9,FIND("/",K9)+1,10))+1,4)),VALUE(LEFT(MID(K9,FIND("/",K9)+1,10),FIND("/",MID(K9,FIND("/",K9)+1,10))-1)),1),0))),0,1),1)+IFERROR(IF(M9>=0,0,1),1)+IFERROR(IF(ISNUMBER(MATCH(N9,Lists!$B$2:$B$7,0)),0,1),1))=0,"OK","ERROR")) -> OK | Q9: =IF(D9="","",TRIM(IF(IFERROR(IF(AND(TRIM(D9)=D9,LEN(D9)>0),0,1),1)=1,"Name; ","")&IF(IFERROR(IF(AND(LEN(E9)=10,ISNUMBER(VALUE(E9))),0,1),1)=1,"Phone; ","")&IF(IFERROR(IF(AND(ISNUMBER(SEARCH("@",F9)),ISNUMBER(SEARCH(".",F9))),0,1),1)=1,"Email; ","")&IF(IFERROR(IF(AND(LEN(J9)=6,ISNUMBER(VALUE(J9))),0,1),1)=1,"Pincode; ","")&IF(IFERROR(IF(ISNUMBER(MATCH(TRIM(I9),Lists!$A$2:$A$20,0)),0,1),1)=1,"State; ","")&IF(IFERROR(IF(AND(LEN(K9)=10,VALUE(LEFT(K9,FIND("/",K9)-1))>=1,VALUE(LEFT(K9,FIND("/",K9)-1))<=31,VALUE(LEFT(MID(K9,FIND("/",K9)+1,10),FIND("/",MID(K9,FIND("/",K9)+1,10))-1))>=1,VALUE(LEFT(MID(K9,FIND("/",K9)+1,10),FIND("/",MID(K9,FIND("/",K9)+1,10))-1))<=12,VALUE(LEFT(K9,FIND("/",K9)-1))<=DAY(EOMONTH(DATE(VALUE(MID(MID(K9,FIND("/",K9)+1,10),FIND("/",MID(K9,FIND("/",K9)+1,10))+1,4)),VALUE(LEFT(MID(K9,FIND("/",K9)+1,10),FIND("/",MID(K9,FIND("/",K9)+1,10))-1)),1),0))),0,1),1)=1,"Date; ","")&IF(IFERROR(IF(M9>=0,0,1),1)=1,"Amount; ","")&IF(IFERROR(IF(ISNUMBER(MATCH(N9,Lists!$B$2:$B$7,0)),0,1),1)=1,"Payment; ",""))) | R9: =IF(D9="","",IF(COUNTIFS($D$2:$D$701,D9,$E$2:$E$701,E9)>1,"DUPLICATE","Unique")) -> Unique
A10: 9 | B10: 1 | C10: CUST00009 | D10: Veer Balay | E10: 9578713315 | F10: veer.balay22@outlook.com | G10: 41, Murty Ganj | H10: Mysuru | I10: Karnataka | J10: 839301 | K10: 16/07/2026 | L10: Wireless Mouse | M10: 3816.28 | N10: Cash | O10: =IFERROR(LEN(C10&D10&E10&F10&G10&H10&I10&J10&K10&L10&M10&N10)/5,0) -> 24.6 | P10: =IF(OR(D10="",C10=""),"",IF((IFERROR(IF(AND(TRIM(D10)=D10,LEN(D10)>0),0,1),1)+IFERROR(IF(AND(LEN(E10)=10,ISNUMBER(VALUE(E10))),0,1),1)+IFERROR(IF(AND(ISNUMBER(SEARCH("@",F10)),ISNUMBER(SEARCH(".",F10))),0,1),1)+IFERROR(IF(AND(LEN(J10)=6,ISNUMBER(VALUE(J10))),0,1),1)+IFERROR(IF(ISNUMBER(MATCH(TRIM(I10),Lists!$A$2:$A$20,0)),0,1),1)+IFERROR(IF(AND(LEN(K10)=10,VALUE(LEFT(K10,FIND("/",K10)-1))>=1,VALUE(LEFT(K10,FIND("/",K10)-1))<=31,VALUE(LEFT(MID(K10,FIND("/",K10)+1,10),FIND("/",MID(K10,FIND("/",K10)+1,10))-1))>=1,VALUE(LEFT(MID(K10,FIND("/",K10)+1,10),FIND("/",MID(K10,FIND("/",K10)+1,10))-1))<=12,VALUE(LEFT(K10,FIND("/",K10)-1))<=DAY(EOMONTH(DATE(VALUE(MID(MID(K10,FIND("/",K10)+1,10),FIND("/",MID(K10,FIND("/",K10)+1,10))+1,4)),VALUE(LEFT(MID(K10,FIND("/",K10)+1,10),FIND("/",MID(K10,FIND("/",K10)+1,10))-1)),1),0))),0,1),1)+IFERROR(IF(M10>=0,0,1),1)+IFERROR(IF(ISNUMBER(MATCH(N10,Lists!$B$2:$B$7,0)),0,1),1))=0,"OK","ERROR")) -> OK | Q10: =IF(D10="","",TRIM(IF(IFERROR(IF(AND(TRIM(D10)=D10,LEN(D10)>0),0,1),1)=1,"Name; ","")&IF(IFERROR(IF(AND(LEN(E10)=10,ISNUMBER(VALUE(E10))),0,1),1)=1,"Phone; ","")&IF(IFERROR(IF(AND(ISNUMBER(SEARCH("@",F10)),ISNUMBER(SEARCH(".",F10))),0,1),1)=1,"Email; ","")&IF(IFERROR(IF(AND(LEN(J10)=6,ISNUMBER(VALUE(J10))),0,1),1)=1,"Pincode; ","")&IF(IFERROR(IF(ISNUMBER(MATCH(TRIM(I10),Lists!$A$2:$A$20,0)),0,1),1)=1,"State; ","")&IF(IFERROR(IF(AND(LEN(K10)=10,VALUE(LEFT(K10,FIND("/",K10)-1))>=1,VALUE(LEFT(K10,FIND("/",K10)-1))<=31,VALUE(LEFT(MID(K10,FIND("/",K10)+1,10),FIND("/",MID(K10,FIND("/",K10)+1,10))-1))>=1,VALUE(LEFT(MID(K10,FIND("/",K10)+1,10),FIND("/",MID(K10,FIND("/",K10)+1,10))-1))<=12,VALUE(LEFT(K10,FIND("/",K10)-1))<=DAY(EOMONTH(DATE(VALUE(MID(MID(K10,FIND("/",K10)+1,10),FIND("/",MID(K10,FIND("/",K10)+1,10))+1,4)),VALUE(LEFT(MID(K10,FIND("/",K10)+1,10),FIND("/",MID(K10,FIND("/",K10)+1,10))-1)),1),0))),0,1),1)=1,"Date; ","")&IF(IFERROR(IF(M10>=0,0,1),1)=1,"Amount; ","")&IF(IFERROR(IF(ISNUMBER(MATCH(N10,Lists!$B$2:$B$7,0)),0,1),1)=1,"Payment; ",""))) | R10: =IF(D10="","",IF(COUNTIFS($D$2:$D$701,D10,$E$2:$E$701,E10)>1,"DUPLICATE","Unique")) -> Unique
A11: 10 | B11: 1 | C11: CUST00010 | D11: Xalak Randhawa | E11: 9473829973 | F11: xalak.randhawa804@yahoo.com | G11: 423, Yohannan Circle | H11: Chennai | I11: Tamil Nadu | J11: 631165 | K11: 17/05/2025 | L11: A4 Paper Ream | M11: 7577.99 | N11: Cheque | O11: =IFERROR(LEN(C11&D11&E11&F11&G11&H11&I11&J11&K11&L11&M11&N11)/5,0) -> 27.8 | P11: =IF(OR(D11="",C11=""),"",IF((IFERROR(IF(AND(TRIM(D11)=D11,LEN(D11)>0),0,1),1)+IFERROR(IF(AND(LEN(E11)=10,ISNUMBER(VALUE(E11))),0,1),1)+IFERROR(IF(AND(ISNUMBER(SEARCH("@",F11)),ISNUMBER(SEARCH(".",F11))),0,1),1)+IFERROR(IF(AND(LEN(J11)=6,ISNUMBER(VALUE(J11))),0,1),1)+IFERROR(IF(ISNUMBER(MATCH(TRIM(I11),Lists!$A$2:$A$20,0)),0,1),1)+IFERROR(IF(AND(LEN(K11)=10,VALUE(LEFT(K11,FIND("/",K11)-1))>=1,VALUE(LEFT(K11,FIND("/",K11)-1))<=31,VALUE(LEFT(MID(K11,FIND("/",K11)+1,10),FIND("/",MID(K11,FIND("/",K11)+1,10))-1))>=1,VALUE(LEFT(MID(K11,FIND("/",K11)+1,10),FIND("/",MID(K11,FIND("/",K11)+1,10))-1))<=12,VALUE(LEFT(K11,FIND("/",K11)-1))<=DAY(EOMONTH(DATE(VALUE(MID(MID(K11,FIND("/",K11)+1,10),FIND("/",MID(K11,FIND("/",K11)+1,10))+1,4)),VALUE(LEFT(MID(K11,FIND("/",K11)+1,10),FIND("/",MID(K11,FIND("/",K11)+1,10))-1)),1),0))),0,1),1)+IFERROR(IF(M11>=0,0,1),1)+IFERROR(IF(ISNUMBER(MATCH(N11,Lists!$B$2:$B$7,0)),0,1),1))=0,"OK","ERROR")) -> OK | Q11: =IF(D11="","",TRIM(IF(IFERROR(IF(AND(TRIM(D11)=D11,LEN(D11)>0),0,1),1)=1,"Name; ","")&IF(IFERROR(IF(AND(LEN(E11)=10,ISNUMBER(VALUE(E11))),0,1),1)=1,"Phone; ","")&IF(IFERROR(IF(AND(ISNUMBER(SEARCH("@",F11)),ISNUMBER(SEARCH(".",F11))),0,1),1)=1,"Email; ","")&IF(IFERROR(IF(AND(LEN(J11)=6,ISNUMBER(VALUE(J11))),0,1),1)=1,"Pincode; ","")&IF(IFERROR(IF(ISNUMBER(MATCH(TRIM(I11),Lists!$A$2:$A$20,0)),0,1),1)=1,"State; ","")&IF(IFERROR(IF(AND(LEN(K11)=10,VALUE(LEFT(K11,FIND("/",K11)-1))>=1,VALUE(LEFT(K11,FIND("/",K11)-1))<=31,VALUE(LEFT(MID(K11,FIND("/",K11)+1,10),FIND("/",MID(K11,FIND("/",K11)+1,10))-1))>=1,VALUE(LEFT(MID(K11,FIND("/",K11)+1,10),FIND("/",MID(K11,FIND("/",K11)+1,10))-1))<=12,VALUE(LEFT(K11,FIND("/",K11)-1))<=DAY(EOMONTH(DATE(VALUE(MID(MID(K11,FIND("/",K11)+1,10),FIND("/",MID(K11,FIND("/",K11)+1,10))+1,4)),VALUE(LEFT(MID(K11,FIND("/",K11)+1,10),FIND("/",MID(K11,FIND("/",K11)+1,10))-1)),1),0))),0,1),1)=1,"Date; ","")&IF(IFERROR(IF(M11>=0,0,1),1)=1,"Amount; ","")&IF(IFERROR(IF(ISNUMBER(MATCH(N11,Lists!$B$2:$B$7,0)),0,1),1)=1,"Payment; ",""))) | R11: =IF(D11="","",IF(COUNTIFS($D$2:$D$701,D11,$E$2:$E$701,E11)>1,"DUPLICATE","Unique")) -> Unique
A12: 11 | B12: 1 | C12: CUST00011 | D12: Priya Rastogi | E12: 9513338726 | F12: priya.rastogi188@yahoo.com | G12: 287, Batta Zila | H12: Kolkata | I12: West Bengal | J12: 731781 | K12: 14/04/2023 | L12: Whiteboard Marker Set | M12: 15987.66 | N12: cashh | O12: =IFERROR(LEN(C12&D12&E12&F12&G12&H12&I12&J12&K12&L12&M12&N12)/5,0) -> 28.2 | P12: =IF(OR(D12="",C12=""),"",IF((IFERROR(IF(AND(TRIM(D12)=D12,LEN(D12)>0),0,1),1)+IFERROR(IF(AND(LEN(E12)=10,ISNUMBER(VALUE(E12))),0,1),1)+IFERROR(IF(AND(ISNUMBER(SEARCH("@",F12)),ISNUMBER(SEARCH(".",F12))),0,1),1)+IFERROR(IF(AND(LEN(J12)=6,ISNUMBER(VALUE(J12))),0,1),1)+IFERROR(IF(ISNUMBER(MATCH(TRIM(I12),Lists!$A$2:$A$20,0)),0,1),1)+IFERROR(IF(AND(LEN(K12)=10,VALUE(LEFT(K12,FIND("/",K12)-1))>=1,VALUE(LEFT(K12,FIND("/",K12)-1))<=31,VALUE(LEFT(MID(K12,FIND("/",K12)+1,10),FIND("/",MID(K12,FIND("/",K12)+1,10))-1))>=1,VALUE(LEFT(MID(K12,FIND("/",K12)+1,10),FIND("/",MID(K12,FIND("/",K12)+1,10))-1))<=12,VALUE(LEFT(K12,FIND("/",K12)-1))<=DAY(EOMONTH(DATE(VALUE(MID(MID(K12,FIND("/",K12)+1,10),FIND("/",MID(K12,FIND("/",K12)+1,10))+1,4)),VALUE(LEFT(MID(K12,FIND("/",K12)+1,10),FIND("/",MID(K12,FIND("/",K12)+1,10))-1)),1),0))),0,1),1)+IFERROR(IF(M12>=0,0,1),1)+IFERROR(IF(ISNUMBER(MATCH(N12,Lists!$B$2:$B$7,0)),0,1),1))=0,"OK","ERROR")) -> ERROR | Q12: =IF(D12="","",TRIM(IF(IFERROR(IF(AND(TRIM(D12)=D12,LEN(D12)>0),0,1),1)=1,"Name; ","")&IF(IFERROR(IF(AND(LEN(E12)=10,ISNUMBER(VALUE(E12))),0,1),1)=1,"Phone; ","")&IF(IFERROR(IF(AND(ISNUMBER(SEARCH("@",F12)),ISNUMBER(SEARCH(".",F12))),0,1),1)=1,"Email; ","")&IF(IFERROR(IF(AND(LEN(J12)=6,ISNUMBER(VALUE(J12))),0,1),1)=1,"Pincode; ","")&IF(IFERROR(IF(ISNUMBER(MATCH(TRIM(I12),Lists!$A$2:$A$20,0)),0,1),1)=1,"State; ","")&IF(IFERROR(IF(AND(LEN(K12)=10,VALUE(LEFT(K12,FIND("/",K12)-1))>=1,VALUE(LEFT(K12,FIND("/",K12)-1))<=31,VALUE(LEFT(MID(K12,FIND("/",K12)+1,10),FIND("/",MID(K12,FIND("/",K12)+1,10))-1))>=1,VALUE(LEFT(MID(K12,FIND("/",K12)+1,10),FIND("/",MID(K12,FIND("/",K12)+1,10))-1))<=12,VALUE(LEFT(K12,FIND("/",K12)-1))<=DAY(EOMONTH(DATE(VALUE(MID(MID(K12,FIND("/",K12)+1,10),FIND("/",MID(K12,FIND("/",K12)+1,10))+1,4)),VALUE(LEFT(MID(K12,FIND("/",K12)+1,10),FIND("/",MID(K12,FIND("/",K12)+1,10))-1)),1),0))),0,1),1)=1,"Date; ","")&IF(IFERROR(IF(M12>=0,0,1),1)=1,"Amount; ","")&IF(IFERROR(IF(ISNUMBER(MATCH(N12,Lists!$B$2:$B$7,0)),0,1),1)=1,"Payment; ",""))) -> Payment; | R12: =IF(D12="","",IF(COUNTIFS($D$2:$D$701,D12,$E$2:$E$701,E12)>1,"DUPLICATE","Unique")) -> Unique
A13: 12 | B13: 1 | C13: CUST00012 | D13: Michael Dutta | E13: 9773602606 | F13: michael.dutta272@yahoo.com | G13: 16/69, Wadhwa Chowk | H13: Patna | I13: Bihar | J13: 468723 | K13: 30/08/2024 | L13: Laptop Stand | M13: 15504.61 | N13: Net Banking | O13: =IFERROR(LEN(C13&D13&E13&F13&G13&H13&I13&J13&K13&L13&M13&N13)/5,0) -> 26.8 | P13: =IF(OR(D13="",C13=""),"",IF((IFERROR(IF(AND(TRIM(D13)=D13,LEN(D13)>0),0,1),1)+IFERROR(IF(AND(LEN(E13)=10,ISNUMBER(VALUE(E13))),0,1),1)+IFERROR(IF(AND(ISNUMBER(SEARCH("@",F13)),ISNUMBER(SEARCH(".",F13))),0,1),1)+IFERROR(IF(AND(LEN(J13)=6,ISNUMBER(VALUE(J13))),0,1),1)+IFERROR(IF(ISNUMBER(MATCH(TRIM(I13),Lists!$A$2:$A$20,0)),0,1),1)+IFERROR(IF(AND(LEN(K13)=10,VALUE(LEFT(K13,FIND("/",K13)-1))>=1,VALUE(LEFT(K13,FIND("/",K13)-1))<=31,VALUE(LEFT(MID(K13,FIND("/",K13)+1,10),FIND("/",MID(K13,FIND("/",K13)+1,10))-1))>=1,VALUE(LEFT(MID(K13,FIND("/",K13)+1,10),FIND("/",MID(K13,FIND("/",K13)+1,10))-1))<=12,VALUE(LEFT(K13,FIND("/",K13)-1))<=DAY(EOMONTH(DATE(VALUE(MID(MID(K13,FIND("/",K13)+1,10),FIND("/",MID(K13,FIND("/",K13)+1,10))+1,4)),VALUE(LEFT(MID(K13,FIND("/",K13)+1,10),FIND("/",MID(K13,FIND("/",K13)+1,10))-1)),1),0))),0,1),1)+IFERROR(IF(M13>=0,0,1),1)+IFERROR(IF(ISNUMBER(MATCH(N13,Lists!$B$2:$B$7,0)),0,1),1))=0,"OK","ERROR")) -> OK | Q13: =IF(D13="","",TRIM(IF(IFERROR(IF(AND(TRIM(D13)=D13,LEN(D13)>0),0,1),1)=1,"Name; ","")&IF(IFERROR(IF(AND(LEN(E13)=10,ISNUMBER(VALUE(E13))),0,1),1)=1,"Phone; ","")&IF(IFERROR(IF(AND(ISNUMBER(SEARCH("@",F13)),ISNUMBER(SEARCH(".",F13))),0,1),1)=1,"Email; ","")&IF(IFERROR(IF(AND(LEN(J13)=6,ISNUMBER(VALUE(J13))),0,1),1)=1,"Pincode; ","")&IF(IFERROR(IF(ISNUMBER(MATCH(TRIM(I13),Lists!$A$2:$A$20,0)),0,1),1)=1,"State; ","")&IF(IFERROR(IF(AND(LEN(K13)=10,VALUE(LEFT(K13,FIND("/",K13)-1))>=1,VALUE(LEFT(K13,FIND("/",K13)-1))<=31,VALUE(LEFT(MID(K13,FIND("/",K13)+1,10),FIND("/",MID(K13,FIND("/",K13)+1,10))-1))>=1,VALUE(LEFT(MID(K13,FIND("/",K13)+1,10),FIND("/",MID(K13,FIND("/",K13)+1,10))-1))<=12,VALUE(LEFT(K13,FIND("/",K13)-1))<=DAY(EOMONTH(DATE(VALUE(MID(MID(K13,FIND("/",K13)+1,10),FIND("/",MID(K13,FIND("/",K13)+1,10))+1,4)),VALUE(LEFT(MID(K13,FIND("/",K13)+1,10),FIND("/",MID(K13,FIND("/",K13)+1,10))-1)),1),0))),0,1),1)=1,"Date; ","")&IF(IFERROR(IF(M13>=0,0,1),1)=1,"Amount; ","")&IF(IFERROR(IF(ISNUMBER(MATCH(N13,Lists!$B$2:$B$7,0)),0,1),1)=1,"Payment; ",""))) | R13: =IF(D13="","",IF(COUNTIFS($D$2:$D$701,D13,$E$2:$E$701,E13)>1,"DUPLICATE","Unique")) -> Unique
... A99: 98 | B99: 2 | C99: CUST00098 | D99: Ekapad Keer | E99: 9454019380 | F99: ekapad.keer936@gmail.com | G99: 161, Sawhney Zila | H99: Ludhiana | I99: Punjab | J99: 620672 | K99: 15/08/2024 | L99: Table Fan | M99: 790.97 | N99: Credit Card | O99: =IFERROR(LEN(C99&D99&E99&F99&G99&H99&I99&J99&K99&L99&M99&N99)/5,0) -> 25.4 | P99: =IF(OR(D99="",C99=""),"",IF((IFERROR(IF(AND(TRIM(D99)=D99,LEN(D99)>0),0,1),1)+IFERROR(IF(AND(LEN(E99)=10,ISNUMBER(VALUE(E99))),0,1),1)+IFERROR(IF(AND(ISNUMBER(SEARCH("@",F99)),ISNUMBER(SEARCH(".",F99))),0,1),1)+IFERROR(IF(AND(LEN(J99)=6,ISNUMBER(VALUE(J99))),0,1),1)+IFERROR(IF(ISNUMBER(MATCH(TRIM(I99),Lists!$A$2:$A$20,0)),0,1),1)+IFERROR(IF(AND(LEN(K99)=10,VALUE(LEFT(K99,FIND("/",K99)-1))>=1,VALUE(LEFT(K99,FIND("/",K99)-1))<=31,VALUE(LEFT(MID(K99,FIND("/",K99)+1,10),FIND("/",MID(K99,FIND("/",K99)+1,10))-1))>=1,VALUE(LEFT(MID(K99,FIND("/",K99)+1,10),FIND("/",MID(K99,FIND("/",K99)+1,10))-1))<=12,VALUE(LEFT(K99,FIND("/",K99)-1))<=DAY(EOMONTH(DATE(VALUE(MID(MID(K99,FIND("/",K99)+1,10),FIND("/",MID(K99,FIND("/",K99)+1,10))+1,4)),VALUE(LEFT(MID(K99,FIND("/",K99)+1,10),FIND("/",MID(K99,FIND("/",K99)+1,10))-1)),1),0))),0,1),1)+IFERROR(IF(M99>=0,0,1),1)+IFERROR(IF(ISNUMBER(MATCH(N99,Lists!$B$2:$B$7,0)),0,1),1))=0,"OK","ERROR")) -> OK | Q99: =IF(D99="","",TRIM(IF(IFERROR(IF(AND(TRIM(D99)=D99,LEN(D99)>0),0,1),1)=1,"Name; ","")&IF(IFERROR(IF(AND(LEN(E99)=10,ISNUMBER(VALUE(E99))),0,1),1)=1,"Phone; ","")&IF(IFERROR(IF(AND(ISNUMBER(SEARCH("@",F99)),ISNUMBER(SEARCH(".",F99))),0,1),1)=1,"Email; ","")&IF(IFERROR(IF(AND(LEN(J99)=6,ISNUMBER(VALUE(J99))),0,1),1)=1,"Pincode; ","")&IF(IFERROR(IF(ISNUMBER(MATCH(TRIM(I99),Lists!$A$2:$A$20,0)),0,1),1)=1,"State; ","")&IF(IFERROR(IF(AND(LEN(K99)=10,VALUE(LEFT(K99,FIND("/",K99)-1))>=1,VALUE(LEFT(K99,FIND("/",K99)-1))<=31,VALUE(LEFT(MID(K99,FIND("/",K99)+1,10),FIND("/",MID(K99,FIND("/",K99)+1,10))-1))>=1,VALUE(LEFT(MID(K99,FIND("/",K99)+1,10),FIND("/",MID(K99,FIND("/",K99)+1,10))-1))<=12,VALUE(LEFT(K99,FIND("/",K99)-1))<=DAY(EOMONTH(DATE(VALUE(MID(MID(K99,FIND("/",K99)+1,10),FIND("/",MID(K99,FIND("/",K99)+1,10))+1,4)),VALUE(LEFT(MID(K99,FIND("/",K99)+1,10),FIND("/",MID(K99,FIND("/",K99)+1,10))-1)),1),0))),0,1),1)=1,"Date; ","")&IF(IFERROR(IF(M99>=0,0,1),1)=1,"Amount; ","")&IF(IFERROR(IF(ISNUMBER(MATCH(N99,Lists!$B$2:$B$7,0)),0,1),1)=1,"Payment; ",""))) | R99: =IF(D99="","",IF(COUNTIFS($D$2:$D$701,D99,$E$2:$E$701,E99)>1,"DUPLICATE","Unique")) -> Unique
A100: 99 | B100: 2 | C100: CUST00099 | E100: 9547887287 | F100: chandani.balakrishnan280@gmail.com | G100: H.No. 04, Prasad Path | H100: Gurugram | I100: Haryana | J100: 152742 | K100: 29/01/2023 | L100: File Organizer | M100: 5525.37 | N100: Credit Card | O100: =IFERROR(LEN(C100&D100&E100&F100&G100&H100&I100&J100&K100&L100&M100&N100)/5,0) -> 27.4 | P100: =IF(OR(D100="",C100=""),"",IF((IFERROR(IF(AND(TRIM(D100)=D100,LEN(D100)>0),0,1),1)+IFERROR(IF(AND(LEN(E100)=10,ISNUMBER(VALUE(E100))),0,1),1)+IFERROR(IF(AND(ISNUMBER(SEARCH("@",F100)),ISNUMBER(SEARCH(".",F100))),0,1),1)+IFERROR(IF(AND(LEN(J100)=6,ISNUMBER(VALUE(J100))),0,1),1)+IFERROR(IF(ISNUMBER(MATCH(TRIM(I100),Lists!$A$2:$A$20,0)),0,1),1)+IFERROR(IF(AND(LEN(K100)=10,VALUE(LEFT(K100,FIND("/",K100)-1))>=1,VALUE(LEFT(K100,FIND("/",K100)-1))<=31,VALUE(LEFT(MID(K100,FIND("/",K100)+1,10),FIND("/",MID(K100,FIND("/",K100)+1,10))-1))>=1,VALUE(LEFT(MID(K100,FIND("/",K100)+1,10),FIND("/",MID(K100,FIND("/",K100)+1,10))-1))<=12,VALUE(LEFT(K100,FIND("/",K100)-1))<=DAY(EOMONTH(DATE(VALUE(MID(MID(K100,FIND("/",K100)+1,10),FIND("/",MID(K100,FIND("/",K100)+1,10))+1,4)),VALUE(LEFT(MID(K100,FIND("/",K100)+1,10),FIND("/",MID(K100,FIND("/",K100)+1,10))-1)),1),0))),0,1),1)+IFERROR(IF(M100>=0,0,1),1)+IFERROR(IF(ISNUMBER(MATCH(N100,Lists!$B$2:$B$7,0)),0,1),1))=0,"OK","ERROR")) | Q100: =IF(D100="","",TRIM(IF(IFERROR(IF(AND(TRIM(D100)=D100,LEN(D100)>0),0,1),1)=1,"Name; ","")&IF(IFERROR(IF(AND(LEN(E100)=10,ISNUMBER(VALUE(E100))),0,1),1)=1,"Phone; ","")&IF(IFERROR(IF(AND(ISNUMBER(SEARCH("@",F100)),ISNUMBER(SEARCH(".",F100))),0,1),1)=1,"Email; ","")&IF(IFERROR(IF(AND(LEN(J100)=6,ISNUMBER(VALUE(J100))),0,1),1)=1,"Pincode; ","")&IF(IFERROR(IF(ISNUMBER(MATCH(TRIM(I100),Lists!$A$2:$A$20,0)),0,1),1)=1,"State; ","")&IF(IFERROR(IF(AND(LEN(K100)=10,VALUE(LEFT(K100,FIND("/",K100)-1))>=1,VALUE(LEFT(K100,FIND("/",K100)-1))<=31,VALUE(LEFT(MID(K100,FIND("/",K100)+1,10),FIND("/",MID(K100,FIND("/",K100)+1,10))-1))>=1,VALUE(LEFT(MID(K100,FIND("/",K100)+1,10),FIND("/",MID(K100,FIND("/",K100)+1,10))-1))<=12,VALUE(LEFT(K100,FIND("/",K100)-1))<=DAY(EOMONTH(DATE(VALUE(MID(MID(K100,FIND("/",K100)+1,10),FIND("/",MID(K100,FIND("/",K100)+1,10))+1,4)),VALUE(LEFT(MID(K100,FIND("/",K100)+1,10),FIND("/",MID(K100,FIND("/",K100)+1,10))-1)),1),0))),0,1),1)=1,"Date; ","")&IF(IFERROR(IF(M100>=0,0,1),1)=1,"Amount; ","")&IF(IFERROR(IF(ISNUMBER(MATCH(N100,Lists!$B$2:$B$7,0)),0,1),1)=1,"Payment; ",""))) | R100: =IF(D100="","",IF(COUNTIFS($D$2:$D$701,D100,$E$2:$E$701,E100)>1,"DUPLICATE","Unique"))
A101: 100 | B101: 2 | C101: CUST00100 | D101: Madhav Konda | E101: 9668516122 | F101: madhav.konda489@yahoo.com | G101: 22/21, Raja | H101: Gurugram | I101: Haryana | J101: 304637 | K101: 30/06/2024 | L101: Printer Cartridge | M101: 4969.74 | N101: Cheque | O101: =IFERROR(LEN(C101&D101&E101&F101&G101&H101&I101&J101&K101&L101&M101&N101)/5,0) -> 25.6 | P101: =IF(OR(D101="",C101=""),"",IF((IFERROR(IF(AND(TRIM(D101)=D101,LEN(D101)>0),0,1),1)+IFERROR(IF(AND(LEN(E101)=10,ISNUMBER(VALUE(E101))),0,1),1)+IFERROR(IF(AND(ISNUMBER(SEARCH("@",F101)),ISNUMBER(SEARCH(".",F101))),0,1),1)+IFERROR(IF(AND(LEN(J101)=6,ISNUMBER(VALUE(J101))),0,1),1)+IFERROR(IF(ISNUMBER(MATCH(TRIM(I101),Lists!$A$2:$A$20,0)),0,1),1)+IFERROR(IF(AND(LEN(K101)=10,VALUE(LEFT(K101,FIND("/",K101)-1))>=1,VALUE(LEFT(K101,FIND("/",K101)-1))<=31,VALUE(LEFT(MID(K101,FIND("/",K101)+1,10),FIND("/",MID(K101,FIND("/",K101)+1,10))-1))>=1,VALUE(LEFT(MID(K101,FIND("/",K101)+1,10),FIND("/",MID(K101,FIND("/",K101)+1,10))-1))<=12,VALUE(LEFT(K101,FIND("/",K101)-1))<=DAY(EOMONTH(DATE(VALUE(MID(MID(K101,FIND("/",K101)+1,10),FIND("/",MID(K101,FIND("/",K101)+1,10))+1,4)),VALUE(LEFT(MID(K101,FIND("/",K101)+1,10),FIND("/",MID(K101,FIND("/",K101)+1,10))-1)),1),0))),0,1),1)+IFERROR(IF(M101>=0,0,1),1)+IFERROR(IF(ISNUMBER(MATCH(N101,Lists!$B$2:$B$7,0)),0,1),1))=0,"OK","ERROR")) -> OK | Q101: =IF(D101="","",TRIM(IF(IFERROR(IF(AND(TRIM(D101)=D101,LEN(D101)>0),0,1),1)=1,"Name; ","")&IF(IFERROR(IF(AND(LEN(E101)=10,ISNUMBER(VALUE(E101))),0,1),1)=1,"Phone; ","")&IF(IFERROR(IF(AND(ISNUMBER(SEARCH("@",F101)),ISNUMBER(SEARCH(".",F101))),0,1),1)=1,"Email; ","")&IF(IFERROR(IF(AND(LEN(J101)=6,ISNUMBER(VALUE(J101))),0,1),1)=1,"Pincode; ","")&IF(IFERROR(IF(ISNUMBER(MATCH(TRIM(I101),Lists!$A$2:$A$20,0)),0,1),1)=1,"State; ","")&IF(IFERROR(IF(AND(LEN(K101)=10,VALUE(LEFT(K101,FIND("/",K101)-1))>=1,VALUE(LEFT(K101,FIND("/",K101)-1))<=31,VALUE(LEFT(MID(K101,FIND("/",K101)+1,10),FIND("/",MID(K101,FIND("/",K101)+1,10))-1))>=1,VALUE(LEFT(MID(K101,FIND("/",K101)+1,10),FIND("/",MID(K101,FIND("/",K101)+1,10))-1))<=12,VALUE(LEFT(K101,FIND("/",K101)-1))<=DAY(EOMONTH(DATE(VALUE(MID(MID(K101,FIND("/",K101)+1,10),FIND("/",MID(K101,FIND("/",K101)+1,10))+1,4)),VALUE(LEFT(MID(K101,FIND("/",K101)+1,10),FIND("/",MID(K101,FIND("/",K101)+1,10))-1)),1),0))),0,1),1)=1,"Date; ","")&IF(IFERROR(IF(M101>=0,0,1),1)=1,"Amount; ","")&IF(IFERROR(IF(ISNUMBER(MATCH(N101,Lists!$B$2:$B$7,0)),0,1),1)=1,"Payment; ",""))) | R101: =IF(D101="","",IF(COUNTIFS($D$2:$D$701,D101,$E$2:$E$701,E101)>1,"DUPLICATE","Unique")) -> Unique
A102: 101 | B102: 3 | C102: CUST00101 | D102: Widisha Dhar | E102: 9530174268 | F102: widisha.dhar946@outlook.com | G102: 47, Andra Road | H102: Gurugram | I102: Haryana | J102: 414593 | K102: 24/03/2024 | L102: LED Desk Lamp | M102: 7754.27 | N102: Debit Card | O102: =IFERROR(LEN(C102&D102&E102&F102&G102&H102&I102&J102&K102&L102&M102&N102)/5,0) -> 26.6 | P102: =IF(OR(D102="",C102=""),"",IF((IFERROR(IF(AND(TRIM(D102)=D102,LEN(D102)>0),0,1),1)+IFERROR(IF(AND(LEN(E102)=10,ISNUMBER(VALUE(E102))),0,1),1)+IFERROR(IF(AND(ISNUMBER(SEARCH("@",F102)),ISNUMBER(SEARCH(".",F102))),0,1),1)+IFERROR(IF(AND(LEN(J102)=6,ISNUMBER(VALUE(J102))),0,1),1)+IFERROR(IF(ISNUMBER(MATCH(TRIM(I102),Lists!$A$2:$A$20,0)),0,1),1)+IFERROR(IF(AND(LEN(K102)=10,VALUE(LEFT(K102,FIND("/",K102)-1))>=1,VALUE(LEFT(K102,FIND("/",K102)-1))<=31,VALUE(LEFT(MID(K102,FIND("/",K102)+1,10),FIND("/",MID(K102,FIND("/",K102)+1,10))-1))>=1,VALUE(LEFT(MID(K102,FIND("/",K102)+1,10),FIND("/",MID(K102,FIND("/",K102)+1,10))-1))<=12,VALUE(LEFT(K102,FIND("/",K102)-1))<=DAY(EOMONTH(DATE(VALUE(MID(MID(K102,FIND("/",K102)+1,10),FIND("/",MID(K102,FIND("/",K102)+1,10))+1,4)),VALUE(LEFT(MID(K102,FIND("/",K102)+1,10),FIND("/",MID(K102,FIND("/",K102)+1,10))-1)),1),0))),0,1),1)+IFERROR(IF(M102>=0,0,1),1)+IFERROR(IF(ISNUMBER(MATCH(N102,Lists!$B$2:$B$7,0)),0,1),1))=0,"OK","ERROR")) -> OK | Q102: =IF(D102="","",TRIM(IF(IFERROR(IF(AND(TRIM(D102)=D102,LEN(D102)>0),0,1),1)=1,"Name; ","")&IF(IFERROR(IF(AND(LEN(E102)=10,ISNUMBER(VALUE(E102))),0,1),1)=1,"Phone; ","")&IF(IFERROR(IF(AND(ISNUMBER(SEARCH("@",F102)),ISNUMBER(SEARCH(".",F102))),0,1),1)=1,"Email; ","")&IF(IFERROR(IF(AND(LEN(J102)=6,ISNUMBER(VALUE(J102))),0,1),1)=1,"Pincode; ","")&IF(IFERROR(IF(ISNUMBER(MATCH(TRIM(I102),Lists!$A$2:$A$20,0)),0,1),1)=1,"State; ","")&IF(IFERROR(IF(AND(LEN(K102)=10,VALUE(LEFT(K102,FIND("/",K102)-1))>=1,VALUE(LEFT(K102,FIND("/",K102)-1))<=31,VALUE(LEFT(MID(K102,FIND("/",K102)+1,10),FIND("/",MID(K102,FIND("/",K102)+1,10))-1))>=1,VALUE(LEFT(MID(K102,FIND("/",K102)+1,10),FIND("/",MID(K102,FIND("/",K102)+1,10))-1))<=12,VALUE(LEFT(K102,FIND("/",K102)-1))<=DAY(EOMONTH(DATE(VALUE(MID(MID(K102,FIND("/",K102)+1,10),FIND("/",MID(K102,FIND("/",K102)+1,10))+1,4)),VALUE(LEFT(MID(K102,FIND("/",K102)+1,10),FIND("/",MID(K102,FIND("/",K102)+1,10))-1)),1),0))),0,1),1)=1,"Date; ","")&IF(IFERROR(IF(M102>=0,0,1),1)=1,"Amount; ","")&IF(IFERROR(IF(ISNUMBER(MATCH(N102,Lists!$B$2:$B$7,0)),0,1),1)=1,"Payment; ",""))) | R102: =IF(D102="","",IF(COUNTIFS($D$2:$D$701,D102,$E$2:$E$701,E102)>1,"DUPLICATE","Unique")) -> Unique
A103: 102 | B103: 3 | C103: CUST00102 | D103: Bhavna Dugar | E103: 9783391878 | F103: bhavna.dugar721@yahoo.com | G103: 59, Samra Road | H103: Warangal | I103: odisha | J103: 191088 | K103: 19/02/2024 | L103: Webcam | M103: 8678.23 | N103: UPI | O103: =IFERROR(LEN(C103&D103&E103&F103&G103&H103&I103&J103&K103&L103&M103&N103)/5,0) -> 23.2 | P103: =IF(OR(D103="",C103=""),"",IF((IFERROR(IF(AND(TRIM(D103)=D103,LEN(D103)>0),0,1),1)+IFERROR(IF(AND(LEN(E103)=10,ISNUMBER(VALUE(E103))),0,1),1)+IFERROR(IF(AND(ISNUMBER(SEARCH("@",F103)),ISNUMBER(SEARCH(".",F103))),0,1),1)+IFERROR(IF(AND(LEN(J103)=6,ISNUMBER(VALUE(J103))),0,1),1)+IFERROR(IF(ISNUMBER(MATCH(TRIM(I103),Lists!$A$2:$A$20,0)),0,1),1)+IFERROR(IF(AND(LEN(K103)=10,VALUE(LEFT(K103,FIND("/",K103)-1))>=1,VALUE(LEFT(K103,FIND("/",K103)-1))<=31,VALUE(LEFT(MID(K103,FIND("/",K103)+1,10),FIND("/",MID(K103,FIND("/",K103)+1,10))-1))>=1,VALUE(LEFT(MID(K103,FIND("/",K103)+1,10),FIND("/",MID(K103,FIND("/",K103)+1,10))-1))<=12,VALUE(LEFT(K103,FIND("/",K103)-1))<=DAY(EOMONTH(DATE(VALUE(MID(MID(K103,FIND("/",K103)+1,10),FIND("/",MID(K103,FIND("/",K103)+1,10))+1,4)),VALUE(LEFT(MID(K103,FIND("/",K103)+1,10),FIND("/",MID(K103,FIND("/",K103)+1,10))-1)),1),0))),0,1),1)+IFERROR(IF(M103>=0,0,1),1)+IFERROR(IF(ISNUMBER(MATCH(N103,Lists!$B$2:$B$7,0)),0,1),1))=0,"OK","ERROR")) -> OK | Q103: =IF(D103="","",TRIM(IF(IFERROR(IF(AND(TRIM(D103)=D103,LEN(D103)>0),0,1),1)=1,"Name; ","")&IF(IFERROR(IF(AND(LEN(E103)=10,ISNUMBER(VALUE(E103))),0,1),1)=1,"Phone; ","")&IF(IFERROR(IF(AND(ISNUMBER(SEARCH("@",F103)),ISNUMBER(SEARCH(".",F103))),0,1),1)=1,"Email; ","")&IF(IFERROR(IF(AND(LEN(J103)=6,ISNUMBER(VALUE(J103))),0,1),1)=1,"Pincode; ","")&IF(IFERROR(IF(ISNUMBER(MATCH(TRIM(I103),Lists!$A$2:$A$20,0)),0,1),1)=1,"State; ","")&IF(IFERROR(IF(AND(LEN(K103)=10,VALUE(LEFT(K103,FIND("/",K103)-1))>=1,VALUE(LEFT(K103,FIND("/",K103)-1))<=31,VALUE(LEFT(MID(K103,FIND("/",K103)+1,10),FIND("/",MID(K103,FIND("/",K103)+1,10))-1))>=1,VALUE(LEFT(MID(K103,FIND("/",K103)+1,10),FIND("/",MID(K103,FIND("/",K103)+1,10))-1))<=12,VALUE(LEFT(K103,FIND("/",K103)-1))<=DAY(EOMONTH(DATE(VALUE(MID(MID(K103,FIND("/",K103)+1,10),FIND("/",MID(K103,FIND("/",K103)+1,10))+1,4)),VALUE(LEFT(MID(K103,FIND("/",K103)+1,10),FIND("/",MID(K103,FIND("/",K103)+1,10))-1)),1),0))),0,1),1)=1,"Date; ","")&IF(IFERROR(IF(M103>=0,0,1),1)=1,"Amount; ","")&IF(IFERROR(IF(ISNUMBER(MATCH(N103,Lists!$B$2:$B$7,0)),0,1),1)=1,"Payment; ",""))) | R103: =IF(D103="","",IF(COUNTIFS($D$2:$D$701,D103,$E$2:$E$701,E103)>1,"DUPLICATE","Unique")) -> Unique
A104: 103 | B104: 3 | C104: CUST00103 | D104: Tanmayi Mittal | E104: 9397187072 | F104: tanmayi.mittal526@yahoo.com | G104: 71, Raj Ganj | H104: Madurai | I104: Tamil Nadu | J104: 790874 | K104: 14/02/2023 | L104: A4 Paper Ream | M104: 4219.42 | N104: Cash | O104: =IFERROR(LEN(C104&D104&E104&F104&G104&H104&I104&J104&K104&L104&M104&N104)/5,0) -> 25.8 | P104: =IF(OR(D104="",C104=""),"",IF((IFERROR(IF(AND(TRIM(D104)=D104,LEN(D104)>0),0,1),1)+IFERROR(IF(AND(LEN(E104)=10,ISNUMBER(VALUE(E104))),0,1),1)+IFERROR(IF(AND(ISNUMBER(SEARCH("@",F104)),ISNUMBER(SEARCH(".",F104))),0,1),1)+IFERROR(IF(AND(LEN(J104)=6,ISNUMBER(VALUE(J104))),0,1),1)+IFERROR(IF(ISNUMBER(MATCH(TRIM(I104),Lists!$A$2:$A$20,0)),0,1),1)+IFERROR(IF(AND(LEN(K104)=10,VALUE(LEFT(K104,FIND("/",K104)-1))>=1,VALUE(LEFT(K104,FIND("/",K104)-1))<=31,VALUE(LEFT(MID(K104,FIND("/",K104)+1,10),FIND("/",MID(K104,FIND("/",K104)+1,10))-1))>=1,VALUE(LEFT(MID(K104,FIND("/",K104)+1,10),FIND("/",MID(K104,FIND("/",K104)+1,10))-1))<=12,VALUE(LEFT(K104,FIND("/",K104)-1))<=DAY(EOMONTH(DATE(VALUE(MID(MID(K104,FIND("/",K104)+1,10),FIND("/",MID(K104,FIND("/",K104)+1,10))+1,4)),VALUE(LEFT(MID(K104,FIND("/",K104)+1,10),FIND("/",MID(K104,FIND("/",K104)+1,10))-1)),1),0))),0,1),1)+IFERROR(IF(M104>=0,0,1),1)+IFERROR(IF(ISNUMBER(MATCH(N104,Lists!$B$2:$B$7,0)),0,1),1))=0,"OK","ERROR")) -> OK | Q104: =IF(D104="","",TRIM(IF(IFERROR(IF(AND(TRIM(D104)=D104,LEN(D104)>0),0,1),1)=1,"Name; ","")&IF(IFERROR(IF(AND(LEN(E104)=10,ISNUMBER(VALUE(E104))),0,1),1)=1,"Phone; ","")&IF(IFERROR(IF(AND(ISNUMBER(SEARCH("@",F104)),ISNUMBER(SEARCH(".",F104))),0,1),1)=1,"Email; ","")&IF(IFERROR(IF(AND(LEN(J104)=6,ISNUMBER(VALUE(J104))),0,1),1)=1,"Pincode; ","")&IF(IFERROR(IF(ISNUMBER(MATCH(TRIM(I104),Lists!$A$2:$A$20,0)),0,1),1)=1,"State; ","")&IF(IFERROR(IF(AND(LEN(K104)=10,VALUE(LEFT(K104,FIND("/",K104)-1))>=1,VALUE(LEFT(K104,FIND("/",K104)-1))<=31,VALUE(LEFT(MID(K104,FIND("/",K104)+1,10),FIND("/",MID(K104,FIND("/",K104)+1,10))-1))>=1,VALUE(LEFT(MID(K104,FIND("/",K104)+1,10),FIND("/",MID(K104,FIND("/",K104)+1,10))-1))<=12,VALUE(LEFT(K104,FIND("/",K104)-1))<=DAY(EOMONTH(DATE(VALUE(MID(MID(K104,FIND("/",K104)+1,10),FIND("/",MID(K104,FIND("/",K104)+1,10))+1,4)),VALUE(LEFT(MID(K104,FIND("/",K104)+1,10),FIND("/",MID(K104,FIND("/",K104)+1,10))-1)),1),0))),0,1),1)=1,"Date; ","")&IF(IFERROR(IF(M104>=0,0,1),1)=1,"Amount; ","")&IF(IFERROR(IF(ISNUMBER(MATCH(N104,Lists!$B$2:$B$7,0)),0,1),1)=1,"Payment; ",""))) | R104: =IF(D104="","",IF(COUNTIFS($D$2:$D$701,D104,$E$2:$E$701,E104)>1,"DUPLICATE","Unique")) -> Unique
A105: 104 | B105: 3 | C105: CUST00104 | D105: Chakrika Merchant | E105: 9651801704 | F105: chakrika.merchant419@gmail.com | G105: 64/090, Taneja | H105: Rohini | I105: Delhi | J105: 265676 | K105: 08/02/2025 | L105: Office Chair | M105: 10986.14 | N105: Cheque | O105: =IFERROR(LEN(C105&D105&E105&F105&G105&H105&I105&J105&K105&L105&M105&N105)/5,0) -> 26.6 | P105: =IF(OR(D105="",C105=""),"",IF((IFERROR(IF(AND(TRIM(D105)=D105,LEN(D105)>0),0,1),1)+IFERROR(IF(AND(LEN(E105)=10,ISNUMBER(VALUE(E105))),0,1),1)+IFERROR(IF(AND(ISNUMBER(SEARCH("@",F105)),ISNUMBER(SEARCH(".",F105))),0,1),1)+IFERROR(IF(AND(LEN(J105)=6,ISNUMBER(VALUE(J105))),0,1),1)+IFERROR(IF(ISNUMBER(MATCH(TRIM(I105),Lists!$A$2:$A$20,0)),0,1),1)+IFERROR(IF(AND(LEN(K105)=10,VALUE(LEFT(K105,FIND("/",K105)-1))>=1,VALUE(LEFT(K105,FIND("/",K105)-1))<=31,VALUE(LEFT(MID(K105,FIND("/",K105)+1,10),FIND("/",MID(K105,FIND("/",K105)+1,10))-1))>=1,VALUE(LEFT(MID(K105,FIND("/",K105)+1,10),FIND("/",MID(K105,FIND("/",K105)+1,10))-1))<=12,VALUE(LEFT(K105,FIND("/",K105)-1))<=DAY(EOMONTH(DATE(VALUE(MID(MID(K105,FIND("/",K105)+1,10),FIND("/",MID(K105,FIND("/",K105)+1,10))+1,4)),VALUE(LEFT(MID(K105,FIND("/",K105)+1,10),FIND("/",MID(K105,FIND("/",K105)+1,10))-1)),1),0))),0,1),1)+IFERROR(IF(M105>=0,0,1),1)+IFERROR(IF(ISNUMBER(MATCH(N105,Lists!$B$2:$B$7,0)),0,1),1))=0,"OK","ERROR")) -> OK | Q105: =IF(D105="","",TRIM(IF(IFERROR(IF(AND(TRIM(D105)=D105,LEN(D105)>0),0,1),1)=1,"Name; ","")&IF(IFERROR(IF(AND(LEN(E105)=10,ISNUMBER(VALUE(E105))),0,1),1)=1,"Phone; ","")&IF(IFERROR(IF(AND(ISNUMBER(SEARCH("@",F105)),ISNUMBER(SEARCH(".",F105))),0,1),1)=1,"Email; ","")&IF(IFERROR(IF(AND(LEN(J105)=6,ISNUMBER(VALUE(J105))),0,1),1)=1,"Pincode; ","")&IF(IFERROR(IF(ISNUMBER(MATCH(TRIM(I105),Lists!$A$2:$A$20,0)),0,1),1)=1,"State; ","")&IF(IFERROR(IF(AND(LEN(K105)=10,VALUE(LEFT(K105,FIND("/",K105)-1))>=1,VALUE(LEFT(K105,FIND("/",K105)-1))<=31,VALUE(LEFT(MID(K105,FIND("/",K105)+1,10),FIND("/",MID(K105,FIND("/",K105)+1,10))-1))>=1,VALUE(LEFT(MID(K105,FIND("/",K105)+1,10),FIND("/",MID(K105,FIND("/",K105)+1,10))-1))<=12,VALUE(LEFT(K105,FIND("/",K105)-1))<=DAY(EOMONTH(DATE(VALUE(MID(MID(K105,FIND("/",K105)+1,10),FIND("/",MID(K105,FIND("/",K105)+1,10))+1,4)),VALUE(LEFT(MID(K105,FIND("/",K105)+1,10),FIND("/",MID(K105,FIND("/",K105)+1,10))-1)),1),0))),0,1),1)=1,"Date; ","")&IF(IFERROR(IF(M105>=0,0,1),1)=1,"Amount; ","")&IF(IFERROR(IF(ISNUMBER(MATCH(N105,Lists!$B$2:$B$7,0)),0,1),1)=1,"Payment; ",""))) | R105: =IF(D105="","",IF(COUNTIFS($D$2:$D$701,D105,$E$2:$E$701,E105)>1,"DUPLICATE","Unique")) -> Unique
A106: 105 | B106: 3 | C106: CUST00105 | D106: Victor Pandey | E106: 9512868230 | F106: victor.pandey775@gmail.com | G106: 39/421, More Nagar | H106: Guwahati | I106: Assam | J106: 478686 | K106: 15/04/2024 | L106: Laptop Stand | M106: 7476.88 | N106: UPI | O106: =IFERROR(LEN(C106&D106&E106&F106&G106&H106&I106&J106&K106&L106&M106&N106)/5,0) -> 25.4 | P106: =IF(OR(D106="",C106=""),"",IF((IFERROR(IF(AND(TRIM(D106)=D106,LEN(D106)>0),0,1),1)+IFERROR(IF(AND(LEN(E106)=10,ISNUMBER(VALUE(E106))),0,1),1)+IFERROR(IF(AND(ISNUMBER(SEARCH("@",F106)),ISNUMBER(SEARCH(".",F106))),0,1),1)+IFERROR(IF(AND(LEN(J106)=6,ISNUMBER(VALUE(J106))),0,1),1)+IFERROR(IF(ISNUMBER(MATCH(TRIM(I106),Lists!$A$2:$A$20,0)),0,1),1)+IFERROR(IF(AND(LEN(K106)=10,VALUE(LEFT(K106,FIND("/",K106)-1))>=1,VALUE(LEFT(K106,FIND("/",K106)-1))<=31,VALUE(LEFT(MID(K106,FIND("/",K106)+1,10),FIND("/",MID(K106,FIND("/",K106)+1,10))-1))>=1,VALUE(LEFT(MID(K106,FIND("/",K106)+1,10),FIND("/",MID(K106,FIND("/",K106)+1,10))-1))<=12,VALUE(LEFT(K106,FIND("/",K106)-1))<=DAY(EOMONTH(DATE(VALUE(MID(MID(K106,FIND("/",K106)+1,10),FIND("/",MID(K106,FIND("/",K106)+1,10))+1,4)),VALUE(LEFT(MID(K106,FIND("/",K106)+1,10),FIND("/",MID(K106,FIND("/",K106)+1,10))-1)),1),0))),0,1),1)+IFERROR(IF(M106>=0,0,1),1)+IFERROR(IF(ISNUMBER(MATCH(N106,Lists!$B$2:$B$7,0)),0,1),1))=0,"OK","ERROR")) -> OK | Q106: =IF(D106="","",TRIM(IF(IFERROR(IF(AND(TRIM(D106)=D106,LEN(D106)>0),0,1),1)=1,"Name; ","")&IF(IFERROR(IF(AND(LEN(E106)=10,ISNUMBER(VALUE(E106))),0,1),1)=1,"Phone; ","")&IF(IFERROR(IF(AND(ISNUMBER(SEARCH("@",F106)),ISNUMBER(SEARCH(".",F106))),0,1),1)=1,"Email; ","")&IF(IFERROR(IF(AND(LEN(J106)=6,ISNUMBER(VALUE(J106))),0,1),1)=1,"Pincode; ","")&IF(IFERROR(IF(ISNUMBER(MATCH(TRIM(I106),Lists!$A$2:$A$20,0)),0,1),1)=1,"State; ","")&IF(IFERROR(IF(AND(LEN(K106)=10,VALUE(LEFT(K106,FIND("/",K106)-1))>=1,VALUE(LEFT(K106,FIND("/",K106)-1))<=31,VALUE(LEFT(MID(K106,FIND("/",K106)+1,10),FIND("/",MID(K106,FIND("/",K106)+1,10))-1))>=1,VALUE(LEFT(MID(K106,FIND("/",K106)+1,10),FIND("/",MID(K106,FIND("/",K106)+1,10))-1))<=12,VALUE(LEFT(K106,FIND("/",K106)-1))<=DAY(EOMONTH(DATE(VALUE(MID(MID(K106,FIND("/",K106)+1,10),FIND("/",MID(K106,FIND("/",K106)+1,10))+1,4)),VALUE(LEFT(MID(K106,FIND("/",K106)+1,10),FIND("/",MID(K106,FIND("/",K106)+1,10))-1)),1),0))),0,1),1)=1,"Date; ","")&IF(IFERROR(IF(M106>=0,0,1),1)=1,"Amount; ","")&IF(IFERROR(IF(ISNUMBER(MATCH(N106,Lists!$B$2:$B$7,0)),0,1),1)=1,"Payment; ",""))) | R106: =IF(D106="","",IF(COUNTIFS($D$2:$D$701,D106,$E$2:$E$701,E106)>1,"DUPLICATE","Unique")) -> Unique
A107: 106 | B107: 3 | C107: CUST00106 | D107: Bahadurjit Patla | E107: 9106903311 | F107: bahadurjit.patla609@gmail.com | G107: H.No. 456, Iyer Street | H107: Bhopal | I107: Madhya Pradesh | J107: 790306 | K107: 17/06/2025 | L107: Laptop Stand | M107: 8727.2 | N107: Cash | O107: =IFERROR(LEN(C107&D107&E107&F107&G107&H107&I107&J107&K107&L107&M107&N107)/5,0) -> 28.8 | P107: =IF(OR(D107="",C107=""),"",IF((IFERROR(IF(AND(TRIM(D107)=D107,LEN(D107)>0),0,1),1)+IFERROR(IF(AND(LEN(E107)=10,ISNUMBER(VALUE(E107))),0,1),1)+IFERROR(IF(AND(ISNUMBER(SEARCH("@",F107)),ISNUMBER(SEARCH(".",F107))),0,1),1)+IFERROR(IF(AND(LEN(J107)=6,ISNUMBER(VALUE(J107))),0,1),1)+IFERROR(IF(ISNUMBER(MATCH(TRIM(I107),Lists!$A$2:$A$20,0)),0,1),1)+IFERROR(IF(AND(LEN(K107)=10,VALUE(LEFT(K107,FIND("/",K107)-1))>=1,VALUE(LEFT(K107,FIND("/",K107)-1))<=31,VALUE(LEFT(MID(K107,FIND("/",K107)+1,10),FIND("/",MID(K107,FIND("/",K107)+1,10))-1))>=1,VALUE(LEFT(MID(K107,FIND("/",K107)+1,10),FIND("/",MID(K107,FIND("/",K107)+1,10))-1))<=12,VALUE(LEFT(K107,FIND("/",K107)-1))<=DAY(EOMONTH(DATE(VALUE(MID(MID(K107,FIND("/",K107)+1,10),FIND("/",MID(K107,FIND("/",K107)+1,10))+1,4)),VALUE(LEFT(MID(K107,FIND("/",K107)+1,10),FIND("/",MID(K107,FIND("/",K107)+1,10))-1)),1),0))),0,1),1)+IFERROR(IF(M107>=0,0,1),1)+IFERROR(IF(ISNUMBER(MATCH(N107,Lists!$B$2:$B$7,0)),0,1),1))=0,"OK","ERROR")) -> OK | Q107: =IF(D107="","",TRIM(IF(IFERROR(IF(AND(TRIM(D107)=D107,LEN(D107)>0),0,1),1)=1,"Name; ","")&IF(IFERROR(IF(AND(LEN(E107)=10,ISNUMBER(VALUE(E107))),0,1),1)=1,"Phone; ","")&IF(IFERROR(IF(AND(ISNUMBER(SEARCH("@",F107)),ISNUMBER(SEARCH(".",F107))),0,1),1)=1,"Email; ","")&IF(IFERROR(IF(AND(LEN(J107)=6,ISNUMBER(VALUE(J107))),0,1),1)=1,"Pincode; ","")&IF(IFERROR(IF(ISNUMBER(MATCH(TRIM(I107),Lists!$A$2:$A$20,0)),0,1),1)=1,"State; ","")&IF(IFERROR(IF(AND(LEN(K107)=10,VALUE(LEFT(K107,FIND("/",K107)-1))>=1,VALUE(LEFT(K107,FIND("/",K107)-1))<=31,VALUE(LEFT(MID(K107,FIND("/",K107)+1,10),FIND("/",MID(K107,FIND("/",K107)+1,10))-1))>=1,VALUE(LEFT(MID(K107,FIND("/",K107)+1,10),FIND("/",MID(K107,FIND("/",K107)+1,10))-1))<=12,VALUE(LEFT(K107,FIND("/",K107)-1))<=DAY(EOMONTH(DATE(VALUE(MID(MID(K107,FIND("/",K107)+1,10),FIND("/",MID(K107,FIND("/",K107)+1,10))+1,4)),VALUE(LEFT(MID(K107,FIND("/",K107)+1,10),FIND("/",MID(K107,FIND("/",K107)+1,10))-1)),1),0))),0,1),1)=1,"Date; ","")&IF(IFERROR(IF(M107>=0,0,1),1)=1,"Amount; ","")&IF(IFERROR(IF(ISNUMBER(MATCH(N107,Lists!$B$2:$B$7,0)),0,1),1)=1,"Payment; ",""))) | R107: =IF(D107="","",IF(COUNTIFS($D$2:$D$701,D107,$E$2:$E$701,E107)>1,"DUPLICATE","Unique")) -> Unique
A108: 107 | B108: 3 | C108: CUST00107 | D108: Jasmit Wali | E108: 9395995342 | F108: jasmit.wali677@outlook.com | G108: 474, Contractor Path | H108: Durg | I108: Chhattisgarh | J108: 364408 | K108: 26/04/2026 | L108: Table Fan | M108: 11815.35 | N108: UPI | O108: =IFERROR(LEN(C108&D108&E108&F108&G108&H108&I108&J108&K108&L108&M108&N108)/5,0) -> 25.6 | P108: =IF(OR(D108="",C108=""),"",IF((IFERROR(IF(AND(TRIM(D108)=D108,LEN(D108)>0),0,1),1)+IFERROR(IF(AND(LEN(E108)=10,ISNUMBER(VALUE(E108))),0,1),1)+IFERROR(IF(AND(ISNUMBER(SEARCH("@",F108)),ISNUMBER(SEARCH(".",F108))),0,1),1)+IFERROR(IF(AND(LEN(J108)=6,ISNUMBER(VALUE(J108))),0,1),1)+IFERROR(IF(ISNUMBER(MATCH(TRIM(I108),Lists!$A$2:$A$20,0)),0,1),1)+IFERROR(IF(AND(LEN(K108)=10,VALUE(LEFT(K108,FIND("/",K108)-1))>=1,VALUE(LEFT(K108,FIND("/",K108)-1))<=31,VALUE(LEFT(MID(K108,FIND("/",K108)+1,10),FIND("/",MID(K108,FIND("/",K108)+1,10))-1))>=1,VALUE(LEFT(MID(K108,FIND("/",K108)+1,10),FIND("/",MID(K108,FIND("/",K108)+1,10))-1))<=12,VALUE(LEFT(K108,FIND("/",K108)-1))<=DAY(EOMONTH(DATE(VALUE(MID(MID(K108,FIND("/",K108)+1,10),FIND("/",MID(K108,FIND("/",K108)+1,10))+1,4)),VALUE(LEFT(MID(K108,FIND("/",K108)+1,10),FIND("/",MID(K108,FIND("/",K108)+1,10))-1)),1),0))),0,1),1)+IFERROR(IF(M108>=0,0,1),1)+IFERROR(IF(ISNUMBER(MATCH(N108,Lists!$B$2:$B$7,0)),0,1),1))=0,"OK","ERROR")) -> OK | Q108: =IF(D108="","",TRIM(IF(IFERROR(IF(AND(TRIM(D108)=D108,LEN(D108)>0),0,1),1)=1,"Name; ","")&IF(IFERROR(IF(AND(LEN(E108)=10,ISNUMBER(VALUE(E108))),0,1),1)=1,"Phone; ","")&IF(IFERROR(IF(AND(ISNUMBER(SEARCH("@",F108)),ISNUMBER(SEARCH(".",F108))),0,1),1)=1,"Email; ","")&IF(IFERROR(IF(AND(LEN(J108)=6,ISNUMBER(VALUE(J108))),0,1),1)=1,"Pincode; ","")&IF(IFERROR(IF(ISNUMBER(MATCH(TRIM(I108),Lists!$A$2:$A$20,0)),0,1),1)=1,"State; ","")&IF(IFERROR(IF(AND(LEN(K108)=10,VALUE(LEFT(K108,FIND("/",K108)-1))>=1,VALUE(LEFT(K108,FIND("/",K108)-1))<=31,VALUE(LEFT(MID(K108,FIND("/",K108)+1,10),FIND("/",MID(K108,FIND("/",K108)+1,10))-1))>=1,VALUE(LEFT(MID(K108,FIND("/",K108)+1,10),FIND("/",MID(K108,FIND("/",K108)+1,10))-1))<=12,VALUE(LEFT(K108,FIND("/",K108)-1))<=DAY(EOMONTH(DATE(VALUE(MID(MID(K108,FIND("/",K108)+1,10),FIND("/",MID(K108,FIND("/",K108)+1,10))+1,4)),VALUE(LEFT(MID(K108,FIND("/",K108)+1,10),FIND("/",MID(K108,FIND("/",K108)+1,10))-1)),1),0))),0,1),1)=1,"Date; ","")&IF(IFERROR(IF(M108>=0,0,1),1)=1,"Amount; ","")&IF(IFERROR(IF(ISNUMBER(MATCH(N108,Lists!$B$2:$B$7,0)),0,1),1)=1,"Payment; ",""))) | R108: =IF(D108="","",IF(COUNTIFS($D$2:$D$701,D108,$E$2:$E$701,E108)>1,"DUPLICATE","Unique")) -> Unique
A109: 108 | B109: 3 | C109: CUST00108 | D109: Faqid Dhaliwal | E109: 9568566246 | F109: faqid.dhaliwal189@outlook.com | G109: 68/516, Lalla Nagar | H109: Vadodara | I109: Gujarat | J109: 733427 | K109: 29/04/2023 | L109: Keyboard | M109: 6719.3 | N109: Debit Card | O109: =IFERROR(LEN(C109&D109&E109&F109&G109&H109&I109&J109&K109&L109&M109&N109)/5,0) -> 27.2 | P109: =IF(OR(D109="",C109=""),"",IF((IFERROR(IF(AND(TRIM(D109)=D109,LEN(D109)>0),0,1),1)+IFERROR(IF(AND(LEN(E109)=10,ISNUMBER(VALUE(E109))),0,1),1)+IFERROR(IF(AND(ISNUMBER(SEARCH("@",F109)),ISNUMBER(SEARCH(".",F109))),0,1),1)+IFERROR(IF(AND(LEN(J109)=6,ISNUMBER(VALUE(J109))),0,1),1)+IFERROR(IF(ISNUMBER(MATCH(TRIM(I109),Lists!$A$2:$A$20,0)),0,1),1)+IFERROR(IF(AND(LEN(K109)=10,VALUE(LEFT(K109,FIND("/",K109)-1))>=1,VALUE(LEFT(K109,FIND("/",K109)-1))<=31,VALUE(LEFT(MID(K109,FIND("/",K109)+1,10),FIND("/",MID(K109,FIND("/",K109)+1,10))-1))>=1,VALUE(LEFT(MID(K109,FIND("/",K109)+1,10),FIND("/",MID(K109,FIND("/",K109)+1,10))-1))<=12,VALUE(LEFT(K109,FIND("/",K109)-1))<=DAY(EOMONTH(DATE(VALUE(MID(MID(K109,FIND("/",K109)+1,10),FIND("/",MID(K109,FIND("/",K109)+1,10))+1,4)),VALUE(LEFT(MID(K109,FIND("/",K109)+1,10),FIND("/",MID(K109,FIND("/",K109)+1,10))-1)),1),0))),0,1),1)+IFERROR(IF(M109>=0,0,1),1)+IFERROR(IF(ISNUMBER(MATCH(N109,Lists!$B$2:$B$7,0)),0,1),1))=0,"OK","ERROR")) -> OK | Q109: =IF(D109="","",TRIM(IF(IFERROR(IF(AND(TRIM(D109)=D109,LEN(D109)>0),0,1),1)=1,"Name; ","")&IF(IFERROR(IF(AND(LEN(E109)=10,ISNUMBER(VALUE(E109))),0,1),1)=1,"Phone; ","")&IF(IFERROR(IF(AND(ISNUMBER(SEARCH("@",F109)),ISNUMBER(SEARCH(".",F109))),0,1),1)=1,"Email; ","")&IF(IFERROR(IF(AND(LEN(J109)=6,ISNUMBER(VALUE(J109))),0,1),1)=1,"Pincode; ","")&IF(IFERROR(IF(ISNUMBER(MATCH(TRIM(I109),Lists!$A$2:$A$20,0)),0,1),1)=1,"State; ","")&IF(IFERROR(IF(AND(LEN(K109)=10,VALUE(LEFT(K109,FIND("/",K109)-1))>=1,VALUE(LEFT(K109,FIND("/",K109)-1))<=31,VALUE(LEFT(MID(K109,FIND("/",K109)+1,10),FIND("/",MID(K109,FIND("/",K109)+1,10))-1))>=1,VALUE(LEFT(MID(K109,FIND("/",K109)+1,10),FIND("/",MID(K109,FIND("/",K109)+1,10))-1))<=12,VALUE(LEFT(K109,FIND("/",K109)-1))<=DAY(EOMONTH(DATE(VALUE(MID(MID(K109,FIND("/",K109)+1,10),FIND("/",MID(K109,FIND("/",K109)+1,10))+1,4)),VALUE(LEFT(MID(K109,FIND("/",K109)+1,10),FIND("/",MID(K109,FIND("/",K109)+1,10))-1)),1),0))),0,1),1)=1,"Date; ","")&IF(IFERROR(IF(M109>=0,0,1),1)=1,"Amount; ","")&IF(IFERROR(IF(ISNUMBER(MATCH(N109,Lists!$B$2:$B$7,0)),0,1),1)=1,"Payment; ",""))) | R109: =IF(D109="","",IF(COUNTIFS($D$2:$D$701,D109,$E$2:$E$701,E109)>1,"DUPLICATE","Unique")) -> Unique
