Workbook

Sheet Dashboard
A1: FINANCIAL MIS DASHBOARD - APRIL 2026 SIMULATION
A2: Nexus Tech Distribution Pvt. Ltd. | Tally Prime + Excel | Figures in Rs | Dummy practice data
A3: ="Data checks: "&Checks!E15 -> Data checks: ALL OK
A4: REVENUE (Sales) | C4: GROSS PROFIT | E4: NET PROFIT / (LOSS) | G4: WORKING CAPITAL | I4: CURRENT RATIO
A5: =Data_TB_PL_BS!B17 -> 300000 | C5: =Data_TB_PL_BS!B22 -> 0 | E5: =Data_TB_PL_BS!B23 -> -50000 | G5: =Data_TB_PL_BS!D28-Data_TB_PL_BS!B30 -> 950000 | I5: =IF(Data_TB_PL_BS!B30=0,0,Data_TB_PL_BS!D28/Data_TB_PL_BS!B30) -> 3.6836158
A6: Taxable sales for the period | C6: ="Gross margin "&TEXT(IF(Data_TB_PL_BS!B17=0,0,Data_TB_PL_BS!B22/Data_TB_PL_BS!B17),"0.0%") -> Gross margin 0.0% | E6: ="Net margin "&TEXT(IF(Data_TB_PL_BS!B17=0,0,Data_TB_PL_BS!B23/Data_TB_PL_BS!B17),"0.0%") -> Net margin -16.7% | G6: Current Assets - Current Liabilities | I6: Current Assets / Current Liabilities
A8: KEY FINANCIALS (Rs) | F8: WORKING CAPITAL (Rs)
A9: Sales | C9: =Data_TB_PL_BS!B17 -> 300000 | F9: HDFC Bank balance | H9: =Data_TB_PL_BS!B37 -> 950000
A10: Purchases | C10: =Data_TB_PL_BS!B19 -> 300000 | F10: Receivables | H10: =Data_TB_PL_BS!B38 -> 354000
A11: Gross Profit | C11: =Data_TB_PL_BS!B22 -> 0 | F11: Payables | H11: =SUM(Data_TB_PL_BS!B39:B41) -> 354000
A12: Indirect Expenses | C12: =Data_TB_PL_BS!B21 -> 50000 | F12: Net Working Capital | H12: =Data_TB_PL_BS!D28-Data_TB_PL_BS!B30 -> 950000
A13: Net Profit / (Loss) | C13: =Data_TB_PL_BS!B23 -> -50000 | F13: Receivables - Payables | H13: =H10-H11 -> 0
A16: TAX POSITION (Rs) | F16: KEY RATIOS
A17: Output GST | C17: =SUM(Data_TB_PL_BS!B42:B44) -> 54000 | F17: Gross margin % | H17: =IF(Data_TB_PL_BS!B17=0,0,Data_TB_PL_BS!B22/Data_TB_PL_BS!B17) -> 0
A18: Input Tax Credit (ITC) | C18: =SUM(Data_TB_PL_BS!B45:B47) -> 54000 | F18: Net profit % | H18: =IF(Data_TB_PL_BS!B17=0,0,Data_TB_PL_BS!B23/Data_TB_PL_BS!B17) -> -0.16666667
A19: Net GST payable / (ITC credit) | C19: =C17-C18 -> 0 | F19: Expenses % of sales | H19: =IF(Data_TB_PL_BS!B17=0,0,Data_TB_PL_BS!B21/Data_TB_PL_BS!B17) -> 0.16666667
A20: TDS deducted | C20: =Data_TB_PL_BS!B48 -> 5000 | F20: Current ratio | H20: =IF(Data_TB_PL_BS!B30=0,0,Data_TB_PL_BS!D28/Data_TB_PL_BS!B30) -> 3.6836158
A21: TDS paid | C21: =Data_TB_PL_BS!B49 -> 5000 | F21: Liabilities-to-equity | H21: =IF((Data_TB_PL_BS!B28+Data_TB_PL_BS!B31-Data_TB_PL_BS!D30)=0,0,(Data_TB_PL_BS!B29+Data_TB_PL_BS!B30)/(Data_TB_PL_BS!B28+Data_TB_PL_BS!B31-Data_TB_PL_BS!D30)) -> 0.37263158
A22: TDS pending | C22: =C20-C21 -> 0
A25: BUDGET vs ACTUAL (Rs)
A26: Particulars | C26: Budget | D26: Actual | E26: Variance | F26: Var % | G26: Status
A27: Sales | C27: =Data_TB_PL_BS!B54 -> 400000 | D27: =Data_TB_PL_BS!B17 -> 300000 | E27: =D27-C27 -> -100000 | F27: =IF(C27=0,0,E27/ABS(C27)) -> -0.25 | G27: =IF(E27=0,"On Budget",IF(E27>=0,"Favourable","Adverse")) -> Adverse
A28: Purchases | C28: =Data_TB_PL_BS!B55 -> 300000 | D28: =Data_TB_PL_BS!B19 -> 300000 | E28: =D28-C28 -> 0 | F28: =IF(C28=0,0,E28/ABS(C28)) -> 0 | G28: =IF(E28=0,"On Budget",IF(E28<=0,"Favourable","Adverse")) -> On Budget
A29: Gross Profit | C29: =C27-C28 -> 100000 | D29: =D27-D28 -> 0 | E29: =D29-C29 -> -100000 | F29: =IF(C29=0,0,E29/ABS(C29)) -> -1 | G29: =IF(E29=0,"On Budget",IF(E29>=0,"Favourable","Adverse")) -> Adverse
A30: Indirect Expenses | C30: =Data_TB_PL_BS!B56 -> 60000 | D30: =Data_TB_PL_BS!B21 -> 50000 | E30: =D30-C30 -> -10000 | F30: =IF(C30=0,0,E30/ABS(C30)) -> -0.16666667 | G30: =IF(E30=0,"On Budget",IF(E30<=0,"Favourable","Adverse")) -> Favourable
A31: Net Profit / (Loss) | C31: =C29-C30 -> 40000 | D31: =D29-D30 -> -50000 | E31: =D31-C31 -> -90000 | F31: =IF(C31=0,0,E31/ABS(C31)) -> -2.25 | G31: =IF(E31=0,"On Budget",IF(E31>=0,"Favourable","Adverse")) -> Adverse
A50: Notes: Dashboard reads only the Data_TB_PL_BS sheet (blue cells). Budget figures are dummy assumptions. Gross Profit is nil because closing stock is not valued in Tally. The rent TDS of Rs 5,000 is a practice entry: under Sec 393, TDS on rent applies only when rent exceeds Rs 50,000 per month.

Sheet AI_Insights
A1: AI-ASSISTED INSIGHTS & FINANCIAL NARRATIVE - APRIL 2026
A2: Nexus Tech Distribution Pvt. Ltd. | AI was used to assist in drafting the management commentary. Financial figures are formula-linked to the Tally source data; the wording is fixed text.
A4: 📌 EXECUTIVE OVERVIEW
A5: 1 | B5: ="Scale: April 2026 revenue is Rs "&TEXT(Data_TB_PL_BS!B17,"[>=10000000]##\,##\,##\,##0;[>=100000]##\,##\,##0;##,##0")&", all from Infotech Solutions Ltd, backed by share capital of Rs "&TEXT(Data_TB_PL_BS!B28,"[>=10000000]##\,##\,##\,##0;[>=100000]##\,##\,##0;##,##0")&". The bank balance is Rs "&TEXT(Data_TB_PL_BS!B37,"[>=10000000]##\,##\,##\,##0;[>=100000]##\,##\,##0;##,##0")&IF(Data_TB_PL_BS!B29=0," and the company has no loans.",".") -> Scale: April 2026 revenue is Rs 3,00,000, all from Infotech Solutions Ltd, backed by share capital of Rs 10,00,000. The bank balance is Rs 9,50,000 and the company has no loans.
A6: 2 | B6: ="Profitability: Gross Profit is Rs "&TEXT(Data_TB_PL_BS!B22,"[>=10000000]##\,##\,##\,##0;[>=100000]##\,##\,##0;##,##0")&" ("&TEXT(Dashboard!H17,"0.0%")&" margin) and the "&IF(Data_TB_PL_BS!B23<0,"net loss","net profit")&" is Rs "&TEXT(ABS(Data_TB_PL_BS!B23),"[>=10000000]##\,##\,##\,##0;[>=100000]##\,##\,##0;##,##0")&" ("&TEXT(Dashboard!H18,"0.0%")&" of sales)."&IF(Data_TB_PL_BS!B22<=0," Purchases equal sales and no closing stock is recorded, so the rent expense is not covered by any margin.","") -> Profitability: Gross Profit is Rs 0 (0.0% margin) and the net loss is Rs 50,000 (-16.7% of sales). Purchases equal sales and no closing stock is recorded, so the rent expense is not covered by any margin.
A7: 3 | B7: ="Position: current ratio is "&TEXT(Dashboard!H20,"0.00")&"x, working capital is Rs "&TEXT(Dashboard!H12,"[>=10000000]##\,##\,##\,##0;[>=100000]##\,##\,##0;##,##0")&" and liabilities-to-equity is "&TEXT(Dashboard!H21,"0.00")&"x. "&IF(Dashboard!C19<=0,"GST payable is nil because input tax credit covers the output tax.","Net GST payable is Rs "&TEXT(Dashboard!C19,"[>=10000000]##\,##\,##\,##0;[>=100000]##\,##\,##0;##,##0")&".")&" TDS pending is Rs "&TEXT(Dashboard!C22,"[>=10000000]##\,##\,##\,##0;[>=100000]##\,##\,##0;##,##0")&"." -> Position: current ratio is 3.68x, working capital is Rs 9,50,000 and liabilities-to-equity is 0.37x. GST payable is nil because input tax credit covers the output tax. TDS pending is Rs 0.
A9: ⚠️ KEY RISKS & ANOMALY ALERTS
A10: # | B10: Alert | C10: Severity | D10: Key figure | E10: Commentary
A11: 1 | B11: Zero gross margin and net loss | C11: =IF(Data_TB_PL_BS!B23<0,"High",IF(Dashboard!H17<0.1,"Medium","Low")) -> High | D11: =Data_TB_PL_BS!B23 -> -50000 | E11: ="Sales and purchases are both Rs "&TEXT(Data_TB_PL_BS!B17,"[>=10000000]##\,##\,##\,##0;[>=100000]##\,##\,##0;##,##0")&", so rent of Rs "&TEXT(Data_TB_PL_BS!B21,"[>=10000000]##\,##\,##\,##0;[>=100000]##\,##\,##0;##,##0")&" creates a net "&IF(Data_TB_PL_BS!B23<0,"loss","profit")&" of Rs "&TEXT(ABS(Data_TB_PL_BS!B23),"[>=10000000]##\,##\,##\,##0;[>=100000]##\,##\,##0;##,##0")&". Closing stock is not valued in Tally; record it and review selling prices." -> Sales and purchases are both Rs 3,00,000, so rent of Rs 50,000 creates a net loss of Rs 50,000. Closing stock is not valued in Tally; record it and review selling prices.
A12: 2 | B12: Customer concentration | C12: =IF($C$28/Data_TB_PL_BS!B17>0.5,"High",IF($C$28/Data_TB_PL_BS!B17>0.3,"Medium","Low")) -> High | D12: =IF(Data_TB_PL_BS!B17=0,0,$C$28/Data_TB_PL_BS!B17) -> 1 | E12: ="Infotech Solutions Ltd accounts for "&TEXT(IF(Data_TB_PL_BS!B17=0,0,$C$28/Data_TB_PL_BS!B17),"0%")&" of revenue. A delay in its payment of Rs "&TEXT(Dashboard!H10,"[>=10000000]##\,##\,##\,##0;[>=100000]##\,##\,##0;##,##0")&" would directly hit cash flow." -> Infotech Solutions Ltd accounts for 100% of revenue. A delay in its payment of Rs 3,54,000 would directly hit cash flow.
A13: 3 | B13: Receivable not yet collected | C13: =IF(Dashboard!H10/(Data_TB_PL_BS!B17+Dashboard!C17)>0.5,"High",IF(Dashboard!H10/(Data_TB_PL_BS!B17+Dashboard!C17)>0.2,"Medium","Low")) -> High | D13: =IF(Data_TB_PL_BS!B17+Dashboard!C17=0,0,Dashboard!H10/(Data_TB_PL_BS!B17+Dashboard!C17)) -> 1 | E13: ="Rs "&TEXT(Dashboard!H10,"[>=10000000]##\,##\,##\,##0;[>=100000]##\,##\,##0;##,##0")&" billed to Infotech Solutions Ltd is still receivable, which is "&TEXT(IF(Data_TB_PL_BS!B17+Dashboard!C17=0,0,Dashboard!H10/(Data_TB_PL_BS!B17+Dashboard!C17)),"0%")&" of the amount billed including GST. It is not yet overdue, as all invoices are dated 1-Apr-26." -> Rs 3,54,000 billed to Infotech Solutions Ltd is still receivable, which is 100% of the amount billed including GST. It is not yet overdue, as all invoices are dated 1-Apr-26.
A14: 4 | B14: Liquidity cover for payables | C14: =IF(Dashboard!H9/Dashboard!H11<1,"High",IF(Dashboard!H9/Dashboard!H11<1.5,"Medium","Low")) -> Low | D14: =IF(Dashboard!H11=0,0,Dashboard!H9/Dashboard!H11) -> 2.6836158 | E14: ="The bank balance of Rs "&TEXT(Dashboard!H9,"[>=10000000]##\,##\,##\,##0;[>=100000]##\,##\,##0;##,##0")&" covers vendor payables of Rs "&TEXT(Dashboard!H11,"[>=10000000]##\,##\,##\,##0;[>=100000]##\,##\,##0;##,##0")&" "&TEXT(IF(Dashboard!H11=0,0,Dashboard!H9/Dashboard!H11),"0.0")&" times, so vendors can be paid without waiting for collections." -> The bank balance of Rs 9,50,000 covers vendor payables of Rs 3,54,000 2.7 times, so vendors can be paid without waiting for collections.
A15: 5 | B15: GST and ITC position | C15: =IF(Dashboard!C19>0,"Medium","Low") -> Low | D15: =Dashboard!C18 -> 54000 | E15: ="Input tax credit of Rs "&TEXT(Dashboard!C18,"[>=10000000]##\,##\,##\,##0;[>=100000]##\,##\,##0;##,##0")&" offsets the output GST of Rs "&TEXT(Dashboard!C17,"[>=10000000]##\,##\,##\,##0;[>=100000]##\,##\,##0;##,##0")&", so no GST is payable in cash. Both purchase invoices are matched with GSTR-2B." -> Input tax credit of Rs 54,000 offsets the output GST of Rs 54,000, so no GST is payable in cash. Both purchase invoices are matched with GSTR-2B.
A17: 🎯 STRATEGIC ACTION PLAN
A18: # | B18: Action | C18: Priority | D18: Timeline | E18: Detail
A19: 1 | B19: Price above purchase cost | C19: High | D19: Next month | E19: ="At a "&TEXT($C$29,"0%")&" gross margin, sales of about Rs "&TEXT(((Data_TB_PL_BS!B19+Data_TB_PL_BS!B18-Data_TB_PL_BS!B20)/(1-$C$29)),"[>=10000000]##\,##\,##\,##0;[>=100000]##\,##\,##0;##,##0")&" on the current cost of goods sold of Rs "&TEXT((Data_TB_PL_BS!B19+Data_TB_PL_BS!B18-Data_TB_PL_BS!B20),"[>=10000000]##\,##\,##\,##0;[>=100000]##\,##\,##0;##,##0")&" would give a gross profit of Rs "&TEXT(((Data_TB_PL_BS!B19+Data_TB_PL_BS!B18-Data_TB_PL_BS!B20)/(1-$C$29)-(Data_TB_PL_BS!B19+Data_TB_PL_BS!B18-Data_TB_PL_BS!B20)),"[>=10000000]##\,##\,##\,##0;[>=100000]##\,##\,##0;##,##0")&", enough to cover the rent of Rs "&TEXT(Data_TB_PL_BS!B21,"[>=10000000]##\,##\,##\,##0;[>=100000]##\,##\,##0;##,##0")&". Review selling prices against purchase cost." -> At a 20% gross margin, sales of about Rs 3,75,000 on the current cost of goods sold of Rs 3,00,000 would give a gross profit of Rs 75,000, enough to cover the rent of Rs 50,000. Review selling prices against purchase cost.
A20: 2 | B20: Value and record closing stock | C20: High | D20: Before month-end close | E20: ="Record the closing stock of unsold goods in Tally so Gross Profit reflects the real position, then refresh the P&L and this dashboard." -> Record the closing stock of unsold goods in Tally so Gross Profit reflects the real position, then refresh the P&L and this dashboard.
A21: 3 | B21: Collect the receivable | C21: Medium | D21: Within 30 days | E21: ="Follow up Infotech Solutions Ltd for Rs "&TEXT(Dashboard!H10,"[>=10000000]##\,##\,##\,##0;[>=100000]##\,##\,##0;##,##0")&" and set a 30-day credit term for future sales." -> Follow up Infotech Solutions Ltd for Rs 3,54,000 and set a 30-day credit term for future sales.
A22: 4 | B22: Add more customers | C22: Medium | D22: This quarter | E22: ="Add 2 to 3 more customers so that no single customer is above 50% of sales." -> Add 2 to 3 more customers so that no single customer is above 50% of sales.
A23: 5 | B23: Keep GST matching up to date | C23: Low | D23: Every month | E23: ="Match every purchase invoice with GSTR-2B before filing GSTR-3B to protect the ITC of Rs "&TEXT(Dashboard!C18,"[>=10000000]##\,##\,##\,##0;[>=100000]##\,##\,##0;##,##0")&"." -> Match every purchase invoice with GSTR-2B before filing GSTR-3B to protect the ITC of Rs 54,000.
A26: INPUTS FROM OTHER SHEETS (blue = type the value from the source sheet)
A28: 1 | B28: Sales to largest customer (Infotech Solutions Ltd) | C28: 300000 | D28: Tally Sales Register
A29: 2 | B29: Target gross margin for planning | C29: 0.2 | D29: Assumption
A31: Note: all other figures are read from Data_TB_PL_BS and the Dashboard, so every number on this sheet comes from the Tally data.

Sheet Data_TB_PL_BS
A1: Source Data - Tally Prime Reports (Nexus Tech Distribution Pvt. Ltd.)
A2: Type or paste the figures exported from Tally into the blue cells. The Dashboard and Checks sheets update automatically. As on 1-Apr-26 (current Tally data), Rs.
A4: A. TRIAL BALANCE (closing balance)
A5: Particulars | B5: Debit | C5: Credit
A6: Capital Account | C6: 1000000
A7: Current Liabilities | B7: 36000 | C7: 390000
A8: Current Assets | B8: 1304000
A9: Sales Accounts | C9: 300000
A10: Purchase Accounts | B10: 300000
A11: Indirect Expenses | B11: 50000
A12: Grand Total | B12: =SUM(B6:B11) -> 1690000 | C12: =SUM(C6:C11) -> 1690000
A15: B. PROFIT & LOSS A/c
A16: Particulars | B16: Amount
A17: Sales Accounts | B17: 300000
A18: Opening Stock | B18: 0
A19: Purchase Accounts | B19: 300000
A20: Closing Stock | B20: 0
A21: Indirect Expenses | B21: 50000
A22: Gross Profit (Sales - Purchases - Opening Stock + Closing Stock) | B22: =B17-B19-B18+B20 -> 0
A23: Net Profit / (Loss) | B23: =B22-B21 -> -50000
A26: C. BALANCE SHEET
A27: Liabilities | B27: Amount | C27: Assets | D27: Amount
A28: Capital Account | B28: 1000000 | C28: Current Assets | D28: 1304000
A29: Loans (Liability) | B29: 0 | C29: Fixed Assets | D29: 0
A30: Current Liabilities | B30: 354000 | C30: Profit & Loss A/c (loss) | D30: =MAX(-B23,0) -> 50000
A31: Profit & Loss A/c (profit) | B31: =MAX(B23,0) -> 0
A32: Total | B32: =SUM(B28:B31) -> 1354000 | C32: Total | D32: =SUM(D28:D31) -> 1354000
A35: D. SUPPORTING DETAILS (from ledgers / Day Book)
A36: Item | B36: Amount | C36: Source / Note
A37: HDFC Bank balance | B37: 950000 | C37: HDFC Bank ledger: capital 10,00,000 less payment 50,000 (rent 45,000 + TDS 5,000)
A38: Receivables - Infotech Solutions Ltd | B38: 354000 | C38: Sales Vch 1 (3,00,000 + CGST 27,000 + SGST 27,000)
A39: Payables - Delta Systems Pvt Ltd | B39: 118000 | C39: Purchase Vch 1
A40: Payables - Global Tech Traders | B40: 236000 | C40: Purchase Vch 2
A41: Payables - Apex Office Realty | B41: 0 | C41: Fully paid
A42: Output CGST | B42: 27000 | C42: CGST A/c, sales
A43: Output SGST | B43: 27000 | C43: SGST A/c, sales
A44: Output IGST | B44: 0 | C44: No inter-state sales
A45: Input CGST | B45: 9000 | C45: Delta purchase
A46: Input SGST | B46: 9000 | C46: Delta purchase
A47: Input IGST | B47: 36000 | C47: Global Tech Traders purchase
...

Sheet Checks
A1: Data Checks
A2: Each check compares two figures from the exported reports. All must show OK before using the Dashboard.
A4: Check | B4: Figure 1 | C4: Figure 2 | D4: Difference | E4: Status
A5: Trial Balance: Debit total = Credit total | B5: =Data_TB_PL_BS!B12 -> 1690000 | C5: =Data_TB_PL_BS!C12 -> 1690000 | D5: =B5-C5 -> 0 | E5: =IF(ABS(D5)<0.5,"OK","CHECK") -> OK
A6: TB Sales = P&L Sales | B6: =Data_TB_PL_BS!C9 -> 300000 | C6: =Data_TB_PL_BS!B17 -> 300000 | D6: =B6-C6 -> 0 | E6: =IF(ABS(D6)<0.5,"OK","CHECK") -> OK
A7: TB Purchases = P&L Purchases | B7: =Data_TB_PL_BS!B10 -> 300000 | C7: =Data_TB_PL_BS!B19 -> 300000 | D7: =B7-C7 -> 0 | E7: =IF(ABS(D7)<0.5,"OK","CHECK") -> OK
A8: TB Indirect Expenses = P&L Indirect Expenses | B8: =Data_TB_PL_BS!B11 -> 50000 | C8: =Data_TB_PL_BS!B21 -> 50000 | D8: =B8-C8 -> 0 | E8: =IF(ABS(D8)<0.5,"OK","CHECK") -> OK
A9: TB Capital = Balance Sheet Capital | B9: =Data_TB_PL_BS!C6 -> 1000000 | C9: =Data_TB_PL_BS!B28 -> 1000000 | D9: =B9-C9 -> 0 | E9: =IF(ABS(D9)<0.5,"OK","CHECK") -> OK
A10: TB Current Assets = Balance Sheet Current Assets | B10: =Data_TB_PL_BS!B8 -> 1304000 | C10: =Data_TB_PL_BS!D28 -> 1304000 | D10: =B10-C10 -> 0 | E10: =IF(ABS(D10)<0.5,"OK","CHECK") -> OK
A11: Balance Sheet: Liabilities total = Assets total | B11: =Data_TB_PL_BS!B32 -> 1354000 | C11: =Data_TB_PL_BS!D32 -> 1354000 | D11: =B11-C11 -> 0 | E11: =IF(ABS(D11)<0.5,"OK","CHECK") -> OK
A12: Current Assets = Bank + Receivables | B12: =Data_TB_PL_BS!D28 -> 1304000 | C12: =Data_TB_PL_BS!B37+Data_TB_PL_BS!B38 -> 1304000 | D12: =B12-C12 -> 0 | E12: =IF(ABS(D12)<0.5,"OK","CHECK") -> OK
A13: Current Liabilities = Payables + Net GST + TDS pending | B13: =Data_TB_PL_BS!B30 -> 354000 | C13: =SUM(Data_TB_PL_BS!B39:B41)+(SUM(Data_TB_PL_BS!B42:B44)-SUM(Data_TB_PL_BS!B45:B47))+(Data_TB_PL_BS!B48-Data_TB_PL_BS!B49) -> 354000 | D13: =B13-C13 -> 0 | E13: =IF(ABS(D13)<0.5,"OK","CHECK") -> OK
A15: OVERALL STATUS | E15: =IF(COUNTIF(E5:E13,"OK")=9,"ALL OK","CHECK DATA") -> ALL OK
